Workbook

Sheet Extrato
C3: Saldo Inicial | D3: Lay CS | E3: Lay Zebra | F3: Botbet | G3: LG Zebra | H3: Valida | I3: Revalida | J3: Masterlist | K3: LTD + 1x1 | L3: Sniperback | M3: Under 4,5 | N3: BnR | O3: Over Limite 2ºT | P3: BetFlow | Q3: Free Fire | R3: Scalping Under 2,5 | S3: LG Favorito | T3: Dutching | U3: Projeto +EV | V3: Over Triplex | W3: Meta 5 Pro | X3: Trading | Y3: Lay Super Zebra | Z3: Longo Prazo | AA3: Over Alavancado | AB3: LTD | AC3: OMQB | AD3: Back FT/HT | AE3: AILA | AF3: Guffo | AG3: Value Bets | AH3: Arbitragem | AI3: SuperOdds | AJ3: Saques e Depósitos | AK3: Ajuste Caixa | AL3: Saldo Fulltbet | AN3: Saldo Inicial | AO3: BetFlow | AP3: Lay Zebra | AQ3: Masterlist | AR3: LG Zebra | AS3: Lay 2x2 | AT3: BnR | AU3: Sniperback | AV3: LTD + 1x1 | AW3: Revalida | AX3: Valida | AY3: LG Favorito | AZ3: Dutching | BA3: Meta 5 Pro | BB3: Back FT/HT | BC3: Saques e Depósitos | BD3: Ajuste | BE3: Saldo BetBra | BG3: Saldo Inicial | BH3: LTD + 1x1 | BI3: Revalida | BJ3: Lay Zebra | BK3: BnR | BL3: LG Zebra | BM3: Dutching | BN3: Saques e Depósitos | BO3: Ajuste | BP3: Saldo Bolsa
B4: 45989 | D4: =SUMIFS(#REF!,#REF!,Extrato!$B4,#REF!,Extrato!D$3) -> #REF! | E4: =SUMIFS(#REF!,#REF!,Extrato!$B4,#REF!,Extrato!E$3) -> #REF! | F4: =SUMIFS(#REF!,#REF!,Extrato!$B4,#REF!,Extrato!F$3) -> #REF! | G4: =SUMIFS(#REF!,#REF!,Extrato!$B4,#REF!,Extrato!G$3) -> #REF! | H4: =SUMIFS(#REF!,#REF!,Extrato!$B4,#REF!,Extrato!H$3) -> #REF! | I4: =SUMIFS(#REF!,#REF!,Extrato!$B4,#REF!,Extrato!I$3) -> #REF! | J4: =SUMIFS(#REF!,#REF!,Extrato!$B4,#REF!,Extrato!J$3) -> #REF! | K4: =SUMIFS(#REF!,#REF!,Extrato!$B4,#REF!,Extrato!K$3) -> #REF! | ... O4: =SUMIFS(#REF!,#REF!,Extrato!$B4,#REF!,Extrato!O$3) -> #REF! | P4: =SUMIF(BetFlow!B:B,B4,BetFlow!J:J) -> 0 | Q4: =SUMIFS(#REF!,#REF!,Extrato!$B4,#REF!,Extrato!Q$3) -> #REF! | R4: =SUMIFS(#REF!,#REF!,Extrato!$B4,#REF!,Extrato!R$3) -> #REF! | S4: =SUMIFS(#REF!,#REF!,Extrato!$B4,#REF!,Extrato!S$3) -> #REF! | T4: =SUMIFS(#REF!,#REF!,Extrato!$B4,#REF!,Extrato!T$3) -> #REF! | U4: =SUMIFS(#REF!,#REF!,Extrato!$B4,#REF!,Extrato!U$3) -> #REF! | V4: =SUMIFS(#REF!,#REF!,Extrato!$B4,#REF!,Extrato!V$3) -> #REF! | W4: =SUMIFS(#REF!,#REF!,Extrato!$B4,#REF!,Extrato!W$3) -> #REF! | X4: =SUMIFS(#REF!,#REF!,Extrato!$B4,#REF!,Extrato!X$3) -> #REF! | ... AI4: =SUMIFS(#REF!,#REF!,Extrato!$B4,#REF!,Extrato!AI$3) -> #REF! | AJ4: 0 | AL4: 1350.05
B5: 45990 | C5: =AL4 -> 1350.05 | D5: =SUMIFS(#REF!,#REF!,Extrato!$B5,#REF!,Extrato!D$3) -> #REF! | E5: =SUMIFS(#REF!,#REF!,Extrato!$B5,#REF!,Extrato!E$3) -> #REF! | F5: =SUMIFS(#REF!,#REF!,Extrato!$B5,#REF!,Extrato!F$3) -> #REF! | G5: =SUMIFS(#REF!,#REF!,Extrato!$B5,#REF!,Extrato!G$3) -> #REF! | H5: =SUMIFS(#REF!,#REF!,Extrato!$B5,#REF!,Extrato!H$3) -> #REF! | I5: =SUMIFS(#REF!,#REF!,Extrato!$B5,#REF!,Extrato!I$3) -> #REF! | J5: =SUMIFS(#REF!,#REF!,Extrato!$B5,#REF!,Extrato!J$3) -> #REF! | K5: =SUMIFS(#REF!,#REF!,Extrato!$B5,#REF!,Extrato!K$3) -> #REF! | ... O5: =SUMIFS(#REF!,#REF!,Extrato!$B5,#REF!,Extrato!O$3) -> #REF! | P5: =SUMIF(BetFlow!B:B,B5,BetFlow!J:J) -> 0 | Q5: =SUMIFS(#REF!,#REF!,Extrato!$B5,#REF!,Extrato!Q$3) -> #REF! | R5: =SUMIFS(#REF!,#REF!,Extrato!$B5,#REF!,Extrato!R$3) -> #REF! | S5: =SUMIFS(#REF!,#REF!,Extrato!$B5,#REF!,Extrato!S$3) -> #REF! | T5: =SUMIFS(#REF!,#REF!,Extrato!$B5,#REF!,Extrato!T$3) -> #REF! | U5: =SUMIFS(#REF!,#REF!,Extrato!$B5,#REF!,Extrato!U$3) -> #REF! | V5: =SUMIFS(#REF!,#REF!,Extrato!$B5,#REF!,Extrato!V$3) -> #REF! | W5: =SUMIFS(#REF!,#REF!,Extrato!$B5,#REF!,Extrato!W$3) -> #REF! | X5: =SUMIFS(#REF!,#REF!,Extrato!$B5,#REF!,Extrato!X$3) -> #REF! | ... AI5: =SUMIFS(#REF!,#REF!,Extrato!$B5,#REF!,Extrato!AI$3) -> #REF! | AJ5: 0 | AK5: -84.15 | AL5: =SUM(C5:AK5) -> #REF!
B6: 45991 | C6: =AL5 -> #REF! | D6: =SUMIFS(#REF!,#REF!,Extrato!$B6,#REF!,Extrato!D$3) -> #REF! | E6: =SUMIFS(#REF!,#REF!,Extrato!$B6,#REF!,Extrato!E$3) -> #REF! | F6: =SUMIFS(#REF!,#REF!,Extrato!$B6,#REF!,Extrato!F$3) -> #REF! | G6: =SUMIFS(#REF!,#REF!,Extrato!$B6,#REF!,Extrato!G$3) -> #REF! | H6: =SUMIFS(#REF!,#REF!,Extrato!$B6,#REF!,Extrato!H$3) -> #REF! | I6: =SUMIFS(#REF!,#REF!,Extrato!$B6,#REF!,Extrato!I$3) -> #REF! | J6: =SUMIFS(#REF!,#REF!,Extrato!$B6,#REF!,Extrato!J$3) -> #REF! | K6: =SUMIFS(#REF!,#REF!,Extrato!$B6,#REF!,Extrato!K$3) -> #REF! | ... O6: =SUMIFS(#REF!,#REF!,Extrato!$B6,#REF!,Extrato!O$3) -> #REF! | P6: =SUMIF(BetFlow!B:B,B6,BetFlow!J:J) -> 0 | Q6: =SUMIFS(#REF!,#REF!,Extrato!$B6,#REF!,Extrato!Q$3) -> #REF! | R6: =SUMIFS(#REF!,#REF!,Extrato!$B6,#REF!,Extrato!R$3) -> #REF! | S6: =SUMIFS(#REF!,#REF!,Extrato!$B6,#REF!,Extrato!S$3) -> #REF! | T6: =SUMIFS(#REF!,#REF!,Extrato!$B6,#REF!,Extrato!T$3) -> #REF! | U6: =SUMIFS(#REF!,#REF!,Extrato!$B6,#REF!,Extrato!U$3) -> #REF! | V6: =SUMIFS(#REF!,#REF!,Extrato!$B6,#REF!,Extrato!V$3) -> #REF! | W6: =SUMIFS(#REF!,#REF!,Extrato!$B6,#REF!,Extrato!W$3) -> #REF! | X6: =SUMIFS(#REF!,#REF!,Extrato!$B6,#REF!,Extrato!X$3) -> #REF! | ... AI6: =SUMIFS(#REF!,#REF!,Extrato!$B6,#REF!,Extrato!AI$3) -> #REF! | AJ6: 0 | AK6: -25.54 | AL6: =SUM(C6:AK6) -> #REF!
B7: 45992 | C7: =AL6 -> #REF! | D7: =SUMIFS(#REF!,#REF!,Extrato!$B7,#REF!,Extrato!D$3) -> #REF! | E7: =SUMIFS(#REF!,#REF!,Extrato!$B7,#REF!,Extrato!E$3) -> #REF! | F7: =SUMIFS(#REF!,#REF!,Extrato!$B7,#REF!,Extrato!F$3) -> #REF! | G7: =SUMIFS(#REF!,#REF!,Extrato!$B7,#REF!,Extrato!G$3) -> #REF! | H7: =SUMIFS(#REF!,#REF!,Extrato!$B7,#REF!,Extrato!H$3) -> #REF! | I7: =SUMIFS(#REF!,#REF!,Extrato!$B7,#REF!,Extrato!I$3) -> #REF! | J7: =SUMIFS(#REF!,#REF!,Extrato!$B7,#REF!,Extrato!J$3) -> #REF! | K7: =SUMIFS(#REF!,#REF!,Extrato!$B7,#REF!,Extrato!K$3) -> #REF! | ... O7: =SUMIFS(#REF!,#REF!,Extrato!$B7,#REF!,Extrato!O$3) -> #REF! | P7: =SUMIF(BetFlow!B:B,B7,BetFlow!J:J) -> 0 | Q7: =SUMIFS(#REF!,#REF!,Extrato!$B7,#REF!,Extrato!Q$3) -> #REF! | R7: =SUMIFS(#REF!,#REF!,Extrato!$B7,#REF!,Extrato!R$3) -> #REF! | S7: =SUMIFS(#REF!,#REF!,Extrato!$B7,#REF!,Extrato!S$3) -> #REF! | T7: =SUMIFS(#REF!,#REF!,Extrato!$B7,#REF!,Extrato!T$3) -> #REF! | U7: =SUMIFS(#REF!,#REF!,Extrato!$B7,#REF!,Extrato!U$3) -> #REF! | V7: =SUMIFS(#REF!,#REF!,Extrato!$B7,#REF!,Extrato!V$3) -> #REF! | W7: =SUMIFS(#REF!,#REF!,Extrato!$B7,#REF!,Extrato!W$3) -> #REF! | X7: =SUMIFS(#REF!,#REF!,Extrato!$B7,#REF!,Extrato!X$3) -> #REF! | ... AI7: =SUMIFS(#REF!,#REF!,Extrato!$B7,#REF!,Extrato!AI$3) -> #REF! | AJ7: 0 | AK7: -1.2 | AL7: =SUM(C7:AK7) -> #REF!
B8: 45993 | C8: =AL7 -> #REF! | D8: =SUMIFS(#REF!,#REF!,Extrato!$B8,#REF!,Extrato!D$3) -> #REF! | E8: =SUMIFS(#REF!,#REF!,Extrato!$B8,#REF!,Extrato!E$3) -> #REF! | F8: =SUMIFS(#REF!,#REF!,Extrato!$B8,#REF!,Extrato!F$3) -> #REF! | G8: =SUMIFS(#REF!,#REF!,Extrato!$B8,#REF!,Extrato!G$3) -> #REF! | H8: =SUMIFS(#REF!,#REF!,Extrato!$B8,#REF!,Extrato!H$3) -> #REF! | I8: =SUMIFS(#REF!,#REF!,Extrato!$B8,#REF!,Extrato!I$3) -> #REF! | J8: =SUMIFS(#REF!,#REF!,Extrato!$B8,#REF!,Extrato!J$3) -> #REF! | K8: =SUMIFS(#REF!,#REF!,Extrato!$B8,#REF!,Extrato!K$3) -> #REF! | ... O8: =SUMIFS(#REF!,#REF!,Extrato!$B8,#REF!,Extrato!O$3) -> #REF! | P8: =SUMIF(BetFlow!B:B,B8,BetFlow!J:J) -> 0 | Q8: =SUMIFS(#REF!,#REF!,Extrato!$B8,#REF!,Extrato!Q$3) -> #REF! | R8: =SUMIFS(#REF!,#REF!,Extrato!$B8,#REF!,Extrato!R$3) -> #REF! | S8: =SUMIFS(#REF!,#REF!,Extrato!$B8,#REF!,Extrato!S$3) -> #REF! | T8: =SUMIFS(#REF!,#REF!,Extrato!$B8,#REF!,Extrato!T$3) -> #REF! | U8: =SUMIFS(#REF!,#REF!,Extrato!$B8,#REF!,Extrato!U$3) -> #REF! | V8: =SUMIFS(#REF!,#REF!,Extrato!$B8,#REF!,Extrato!V$3) -> #REF! | W8: =SUMIFS(#REF!,#REF!,Extrato!$B8,#REF!,Extrato!W$3) -> #REF! | X8: =SUMIFS(#REF!,#REF!,Extrato!$B8,#REF!,Extrato!X$3) -> #REF! | ... AI8: =SUMIFS(#REF!,#REF!,Extrato!$B8,#REF!,Extrato!AI$3) -> #REF! | AJ8: 0 | AK8: 7.03 | AL8: =SUM(C8:AK8) -> #REF!
B9: 45994 | C9: =AL8 -> #REF! | D9: =SUMIFS(#REF!,#REF!,Extrato!$B9,#REF!,Extrato!D$3) -> #REF! | E9: =SUMIFS(#REF!,#REF!,Extrato!$B9,#REF!,Extrato!E$3) -> #REF! | F9: =SUMIFS(#REF!,#REF!,Extrato!$B9,#REF!,Extrato!F$3) -> #REF! | G9: =SUMIFS(#REF!,#REF!,Extrato!$B9,#REF!,Extrato!G$3) -> #REF! | H9: =SUMIFS(#REF!,#REF!,Extrato!$B9,#REF!,Extrato!H$3) -> #REF! | I9: =SUMIFS(#REF!,#REF!,Extrato!$B9,#REF!,Extrato!I$3) -> #REF! | J9: =SUMIFS(#REF!,#REF!,Extrato!$B9,#REF!,Extrato!J$3) -> #REF! | K9: =SUMIFS(#REF!,#REF!,Extrato!$B9,#REF!,Extrato!K$3) -> #REF! | ... O9: =SUMIFS(#REF!,#REF!,Extrato!$B9,#REF!,Extrato!O$3) -> #REF! | P9: =SUMIF(BetFlow!B:B,B9,BetFlow!J:J) -> 0 | Q9: =SUMIFS(#REF!,#REF!,Extrato!$B9,#REF!,Extrato!Q$3) -> #REF! | R9: =SUMIFS(#REF!,#REF!,Extrato!$B9,#REF!,Extrato!R$3) -> #REF! | S9: =SUMIFS(#REF!,#REF!,Extrato!$B9,#REF!,Extrato!S$3) -> #REF! | T9: =SUMIFS(#REF!,#REF!,Extrato!$B9,#REF!,Extrato!T$3) -> #REF! | U9: =SUMIFS(#REF!,#REF!,Extrato!$B9,#REF!,Extrato!U$3) -> #REF! | V9: =SUMIFS(#REF!,#REF!,Extrato!$B9,#REF!,Extrato!V$3) -> #REF! | W9: =SUMIFS(#REF!,#REF!,Extrato!$B9,#REF!,Extrato!W$3) -> #REF! | X9: =SUMIFS(#REF!,#REF!,Extrato!$B9,#REF!,Extrato!X$3) -> #REF! | ... AI9: =SUMIFS(#REF!,#REF!,Extrato!$B9,#REF!,Extrato!AI$3) -> #REF! | AJ9: 0 | AK9: 2.61 | AL9: =SUM(C9:AK9) -> #REF!
B10: 45995 | C10: =AL9 -> #REF! | D10: =SUMIFS(#REF!,#REF!,Extrato!$B10,#REF!,Extrato!D$3) -> #REF! | E10: =SUMIFS(#REF!,#REF!,Extrato!$B10,#REF!,Extrato!E$3) -> #REF! | F10: =SUMIFS(#REF!,#REF!,Extrato!$B10,#REF!,Extrato!F$3) -> #REF! | G10: =SUMIFS(#REF!,#REF!,Extrato!$B10,#REF!,Extrato!G$3) -> #REF! | H10: =SUMIFS(#REF!,#REF!,Extrato!$B10,#REF!,Extrato!H$3) -> #REF! | I10: =SUMIFS(#REF!,#REF!,Extrato!$B10,#REF!,Extrato!I$3) -> #REF! | J10: =SUMIFS(#REF!,#REF!,Extrato!$B10,#REF!,Extrato!J$3) -> #REF! | K10: =SUMIFS(#REF!,#REF!,Extrato!$B10,#REF!,Extrato!K$3) -> #REF! | ... O10: =SUMIFS(#REF!,#REF!,Extrato!$B10,#REF!,Extrato!O$3) -> #REF! | P10: =SUMIF(BetFlow!B:B,B10,BetFlow!J:J) -> 0 | Q10: =SUMIFS(#REF!,#REF!,Extrato!$B10,#REF!,Extrato!Q$3) -> #REF! | R10: =SUMIFS(#REF!,#REF!,Extrato!$B10,#REF!,Extrato!R$3) -> #REF! | S10: =SUMIFS(#REF!,#REF!,Extrato!$B10,#REF!,Extrato!S$3) -> #REF! | T10: =SUMIFS(#REF!,#REF!,Extrato!$B10,#REF!,Extrato!T$3) -> #REF! | U10: =SUMIFS(#REF!,#REF!,Extrato!$B10,#REF!,Extrato!U$3) -> #REF! | V10: =SUMIFS(#REF!,#REF!,Extrato!$B10,#REF!,Extrato!V$3) -> #REF! | W10: =SUMIFS(#REF!,#REF!,Extrato!$B10,#REF!,Extrato!W$3) -> #REF! | X10: =SUMIFS(#REF!,#REF!,Extrato!$B10,#REF!,Extrato!X$3) -> #REF! | ... AI10: =SUMIFS(#REF!,#REF!,Extrato!$B10,#REF!,Extrato!AI$3) -> #REF! | AJ10: 0 | AK10: 0.01 | AL10: =SUM(C10:AK10) -> #REF!
B11: 45996 | C11: =AL10 -> #REF! | D11: =SUMIFS(#REF!,#REF!,Extrato!$B11,#REF!,Extrato!D$3) -> #REF! | E11: =SUMIFS(#REF!,#REF!,Extrato!$B11,#REF!,Extrato!E$3) -> #REF! | F11: =SUMIFS(#REF!,#REF!,Extrato!$B11,#REF!,Extrato!F$3) -> #REF! | G11: =SUMIFS(#REF!,#REF!,Extrato!$B11,#REF!,Extrato!G$3) -> #REF! | H11: =SUMIFS(#REF!,#REF!,Extrato!$B11,#REF!,Extrato!H$3) -> #REF! | I11: =SUMIFS(#REF!,#REF!,Extrato!$B11,#REF!,Extrato!I$3) -> #REF! | J11: =SUMIFS(#REF!,#REF!,Extrato!$B11,#REF!,Extrato!J$3) -> #REF! | K11: =SUMIFS(#REF!,#REF!,Extrato!$B11,#REF!,Extrato!K$3) -> #REF! | ... O11: =SUMIFS(#REF!,#REF!,Extrato!$B11,#REF!,Extrato!O$3) -> #REF! | P11: =SUMIF(BetFlow!B:B,B11,BetFlow!J:J) -> 0 | Q11: =SUMIFS(#REF!,#REF!,Extrato!$B11,#REF!,Extrato!Q$3) -> #REF! | R11: =SUMIFS(#REF!,#REF!,Extrato!$B11,#REF!,Extrato!R$3) -> #REF! | S11: =SUMIFS(#REF!,#REF!,Extrato!$B11,#REF!,Extrato!S$3) -> #REF! | T11: =SUMIFS(#REF!,#REF!,Extrato!$B11,#REF!,Extrato!T$3) -> #REF! | U11: =SUMIFS(#REF!,#REF!,Extrato!$B11,#REF!,Extrato!U$3) -> #REF! | V11: =SUMIFS(#REF!,#REF!,Extrato!$B11,#REF!,Extrato!V$3) -> #REF! | W11: =SUMIFS(#REF!,#REF!,Extrato!$B11,#REF!,Extrato!W$3) -> #REF! | X11: =SUMIFS(#REF!,#REF!,Extrato!$B11,#REF!,Extrato!X$3) -> #REF! | ... AI11: =SUMIFS(#REF!,#REF!,Extrato!$B11,#REF!,Extrato!AI$3) -> #REF! | AJ11: 0 | AL11: =SUM(C11:AK11) -> #REF!
B12: 45997 | C12: =AL11 -> #REF! | D12: =SUMIFS(#REF!,#REF!,Extrato!$B12,#REF!,Extrato!D$3) -> #REF! | E12: =SUMIFS(#REF!,#REF!,Extrato!$B12,#REF!,Extrato!E$3) -> #REF! | F12: =SUMIFS(#REF!,#REF!,Extrato!$B12,#REF!,Extrato!F$3) -> #REF! | G12: =SUMIFS(#REF!,#REF!,Extrato!$B12,#REF!,Extrato!G$3) -> #REF! | H12: =SUMIFS(#REF!,#REF!,Extrato!$B12,#REF!,Extrato!H$3) -> #REF! | I12: =SUMIFS(#REF!,#REF!,Extrato!$B12,#REF!,Extrato!I$3) -> #REF! | J12: =SUMIFS(#REF!,#REF!,Extrato!$B12,#REF!,Extrato!J$3) -> #REF! | K12: =SUMIFS(#REF!,#REF!,Extrato!$B12,#REF!,Extrato!K$3) -> #REF! | ... O12: =SUMIFS(#REF!,#REF!,Extrato!$B12,#REF!,Extrato!O$3) -> #REF! | P12: =SUMIF(BetFlow!B:B,B12,BetFlow!J:J) -> 0 | Q12: =SUMIFS(#REF!,#REF!,Extrato!$B12,#REF!,Extrato!Q$3) -> #REF! | R12: =SUMIFS(#REF!,#REF!,Extrato!$B12,#REF!,Extrato!R$3) -> #REF! | S12: =SUMIFS(#REF!,#REF!,Extrato!$B12,#REF!,Extrato!S$3) -> #REF! | T12: =SUMIFS(#REF!,#REF!,Extrato!$B12,#REF!,Extrato!T$3) -> #REF! | U12: =SUMIFS(#REF!,#REF!,Extrato!$B12,#REF!,Extrato!U$3) -> #REF! | V12: =SUMIFS(#REF!,#REF!,Extrato!$B12,#REF!,Extrato!V$3) -> #REF! | W12: =SUMIFS(#REF!,#REF!,Extrato!$B12,#REF!,Extrato!W$3) -> #REF! | X12: =SUMIFS(#REF!,#REF!,Extrato!$B12,#REF!,Extrato!X$3) -> #REF! | ... AI12: =SUMIFS(#REF!,#REF!,Extrato!$B12,#REF!,Extrato!AI$3) -> #REF! | AJ12: 0 | AK12: -0.02 | AL12: =SUM(C12:AK12) -> #REF!
B13: 45998 | C13: =AL12 -> #REF! | D13: =SUMIFS(#REF!,#REF!,Extrato!$B13,#REF!,Extrato!D$3) -> #REF! | E13: =SUMIFS(#REF!,#REF!,Extrato!$B13,#REF!,Extrato!E$3) -> #REF! | F13: =SUMIFS(#REF!,#REF!,Extrato!$B13,#REF!,Extrato!F$3) -> #REF! | G13: =SUMIFS(#REF!,#REF!,Extrato!$B13,#REF!,Extrato!G$3) -> #REF! | H13: =SUMIFS(#REF!,#REF!,Extrato!$B13,#REF!,Extrato!H$3) -> #REF! | I13: =SUMIFS(#REF!,#REF!,Extrato!$B13,#REF!,Extrato!I$3) -> #REF! | J13: =SUMIFS(#REF!,#REF!,Extrato!$B13,#REF!,Extrato!J$3) -> #REF! | K13: =SUMIFS(#REF!,#REF!,Extrato!$B13,#REF!,Extrato!K$3) -> #REF! | ... O13: =SUMIFS(#REF!,#REF!,Extrato!$B13,#REF!,Extrato!O$3) -> #REF! | P13: =SUMIF(BetFlow!B:B,B13,BetFlow!J:J) -> 0 | Q13: =SUMIFS(#REF!,#REF!,Extrato!$B13,#REF!,Extrato!Q$3) -> #REF! | R13: =SUMIFS(#REF!,#REF!,Extrato!$B13,#REF!,Extrato!R$3) -> #REF! | S13: =SUMIFS(#REF!,#REF!,Extrato!$B13,#REF!,Extrato!S$3) -> #REF! | T13: =SUMIFS(#REF!,#REF!,Extrato!$B13,#REF!,Extrato!T$3) -> #REF! | U13: =SUMIFS(#REF!,#REF!,Extrato!$B13,#REF!,Extrato!U$3) -> #REF! | V13: =SUMIFS(#REF!,#REF!,Extrato!$B13,#REF!,Extrato!V$3) -> #REF! | W13: =SUMIFS(#REF!,#REF!,Extrato!$B13,#REF!,Extrato!W$3) -> #REF! | X13: =SUMIFS(#REF!,#REF!,Extrato!$B13,#REF!,Extrato!X$3) -> #REF! | ... AI13: =SUMIFS(#REF!,#REF!,Extrato!$B13,#REF!,Extrato!AI$3) -> #REF! | AJ13: 0 | AL13: =SUM(C13:AK13) -> #REF!
B14: 45999 | C14: =AL13 -> #REF! | D14: =SUMIFS(#REF!,#REF!,Extrato!$B14,#REF!,Extrato!D$3) -> #REF! | E14: =SUMIFS(#REF!,#REF!,Extrato!$B14,#REF!,Extrato!E$3) -> #REF! | F14: =SUMIFS(#REF!,#REF!,Extrato!$B14,#REF!,Extrato!F$3) -> #REF! | G14: =SUMIFS(#REF!,#REF!,Extrato!$B14,#REF!,Extrato!G$3) -> #REF! | H14: =SUMIFS(#REF!,#REF!,Extrato!$B14,#REF!,Extrato!H$3) -> #REF! | I14: =SUMIFS(#REF!,#REF!,Extrato!$B14,#REF!,Extrato!I$3) -> #REF! | J14: =SUMIFS(#REF!,#REF!,Extrato!$B14,#REF!,Extrato!J$3) -> #REF! | K14: =SUMIFS(#REF!,#REF!,Extrato!$B14,#REF!,Extrato!K$3) -> #REF! | ... O14: =SUMIFS(#REF!,#REF!,Extrato!$B14,#REF!,Extrato!O$3) -> #REF! | P14: =SUMIF(BetFlow!B:B,B14,BetFlow!J:J) -> 0 | Q14: =SUMIFS(#REF!,#REF!,Extrato!$B14,#REF!,Extrato!Q$3) -> #REF! | R14: =SUMIFS(#REF!,#REF!,Extrato!$B14,#REF!,Extrato!R$3) -> #REF! | S14: =SUMIFS(#REF!,#REF!,Extrato!$B14,#REF!,Extrato!S$3) -> #REF! | T14: =SUMIFS(#REF!,#REF!,Extrato!$B14,#REF!,Extrato!T$3) -> #REF! | U14: =SUMIFS(#REF!,#REF!,Extrato!$B14,#REF!,Extrato!U$3) -> #REF! | V14: =SUMIFS(#REF!,#REF!,Extrato!$B14,#REF!,Extrato!V$3) -> #REF! | W14: =SUMIFS(#REF!,#REF!,Extrato!$B14,#REF!,Extrato!W$3) -> #REF! | X14: =SUMIFS(#REF!,#REF!,Extrato!$B14,#REF!,Extrato!X$3) -> #REF! | ... AI14: =SUMIFS(#REF!,#REF!,Extrato!$B14,#REF!,Extrato!AI$3) -> #REF! | AJ14: 0 | AK14: -0.02 | AL14: =SUM(C14:AK14) -> #REF!
B15: 46000 | C15: =AL14 -> #REF! | D15: =SUMIFS(#REF!,#REF!,Extrato!$B15,#REF!,Extrato!D$3) -> #REF! | E15: =SUMIFS(#REF!,#REF!,Extrato!$B15,#REF!,Extrato!E$3) -> #REF! | F15: =SUMIFS(#REF!,#REF!,Extrato!$B15,#REF!,Extrato!F$3) -> #REF! | G15: =SUMIFS(#REF!,#REF!,Extrato!$B15,#REF!,Extrato!G$3) -> #REF! | H15: =SUMIFS(#REF!,#REF!,Extrato!$B15,#REF!,Extrato!H$3) -> #REF! | I15: =SUMIFS(#REF!,#REF!,Extrato!$B15,#REF!,Extrato!I$3) -> #REF! | J15: =SUMIFS(#REF!,#REF!,Extrato!$B15,#REF!,Extrato!J$3) -> #REF! | K15: =SUMIFS(#REF!,#REF!,Extrato!$B15,#REF!,Extrato!K$3) -> #REF! | ... O15: =SUMIFS(#REF!,#REF!,Extrato!$B15,#REF!,Extrato!O$3) -> #REF! | P15: =SUMIF(BetFlow!B:B,B15,BetFlow!J:J) -> 0 | Q15: =SUMIFS(#REF!,#REF!,Extrato!$B15,#REF!,Extrato!Q$3) -> #REF! | R15: =SUMIFS(#REF!,#REF!,Extrato!$B15,#REF!,Extrato!R$3) -> #REF! | S15: =SUMIFS(#REF!,#REF!,Extrato!$B15,#REF!,Extrato!S$3) -> #REF! | T15: =SUMIFS(#REF!,#REF!,Extrato!$B15,#REF!,Extrato!T$3) -> #REF! | U15: =SUMIFS(#REF!,#REF!,Extrato!$B15,#REF!,Extrato!U$3) -> #REF! | V15: =SUMIFS(#REF!,#REF!,Extrato!$B15,#REF!,Extrato!V$3) -> #REF! | W15: =SUMIFS(#REF!,#REF!,Extrato!$B15,#REF!,Extrato!W$3) -> #REF! | X15: =SUMIFS(#REF!,#REF!,Extrato!$B15,#REF!,Extrato!X$3) -> #REF! | ... AI15: =SUMIFS(#REF!,#REF!,Extrato!$B15,#REF!,Extrato!AI$3) -> #REF! | AJ15: 0 | AL15: =SUM(C15:AK15) -> #REF!
B16: 46001 | C16: =AL15 -> #REF! | D16: =SUMIFS(#REF!,#REF!,Extrato!$B16,#REF!,Extrato!D$3) -> #REF! | E16: =SUMIFS(#REF!,#REF!,Extrato!$B16,#REF!,Extrato!E$3) -> #REF! | F16: =SUMIFS(#REF!,#REF!,Extrato!$B16,#REF!,Extrato!F$3) -> #REF! | G16: =SUMIFS(#REF!,#REF!,Extrato!$B16,#REF!,Extrato!G$3) -> #REF! | H16: =SUMIFS(#REF!,#REF!,Extrato!$B16,#REF!,Extrato!H$3) -> #REF! | I16: =SUMIFS(#REF!,#REF!,Extrato!$B16,#REF!,Extrato!I$3) -> #REF! | J16: =SUMIFS(#REF!,#REF!,Extrato!$B16,#REF!,Extrato!J$3) -> #REF! | K16: =SUMIFS(#REF!,#REF!,Extrato!$B16,#REF!,Extrato!K$3) -> #REF! | ... O16: =SUMIFS(#REF!,#REF!,Extrato!$B16,#REF!,Extrato!O$3) -> #REF! | P16: =SUMIF(BetFlow!B:B,B16,BetFlow!J:J) -> 0 | Q16: =SUMIFS(#REF!,#REF!,Extrato!$B16,#REF!,Extrato!Q$3) -> #REF! | R16: =SUMIFS(#REF!,#REF!,Extrato!$B16,#REF!,Extrato!R$3) -> #REF! | S16: =SUMIFS(#REF!,#REF!,Extrato!$B16,#REF!,Extrato!S$3) -> #REF! | T16: =SUMIFS(#REF!,#REF!,Extrato!$B16,#REF!,Extrato!T$3) -> #REF! | U16: =SUMIFS(#REF!,#REF!,Extrato!$B16,#REF!,Extrato!U$3) -> #REF! | V16: =SUMIFS(#REF!,#REF!,Extrato!$B16,#REF!,Extrato!V$3) -> #REF! | W16: =SUMIFS(#REF!,#REF!,Extrato!$B16,#REF!,Extrato!W$3) -> #REF! | X16: =SUMIFS(#REF!,#REF!,Extrato!$B16,#REF!,Extrato!X$3) -> #REF! | ... AI16: =SUMIFS(#REF!,#REF!,Extrato!$B16,#REF!,Extrato!AI$3) -> #REF! | AJ16: 0 | AK16: -0.01 | AL16: =SUM(C16:AK16) -> #REF!
B17: 46002 | C17: =AL16 -> #REF! | D17: =SUMIFS(#REF!,#REF!,Extrato!$B17,#REF!,Extrato!D$3) -> #REF! | E17: =SUMIFS(#REF!,#REF!,Extrato!$B17,#REF!,Extrato!E$3) -> #REF! | F17: =SUMIFS(#REF!,#REF!,Extrato!$B17,#REF!,Extrato!F$3) -> #REF! | G17: =SUMIFS(#REF!,#REF!,Extrato!$B17,#REF!,Extrato!G$3) -> #REF! | H17: =SUMIFS(#REF!,#REF!,Extrato!$B17,#REF!,Extrato!H$3) -> #REF! | I17: =SUMIFS(#REF!,#REF!,Extrato!$B17,#REF!,Extrato!I$3) -> #REF! | J17: =SUMIFS(#REF!,#REF!,Extrato!$B17,#REF!,Extrato!J$3) -> #REF! | K17: =SUMIFS(#REF!,#REF!,Extrato!$B17,#REF!,Extrato!K$3) -> #REF! | ... O17: =SUMIFS(#REF!,#REF!,Extrato!$B17,#REF!,Extrato!O$3) -> #REF! | P17: =SUMIF(BetFlow!B:B,B17,BetFlow!J:J) -> 0 | Q17: =SUMIFS(#REF!,#REF!,Extrato!$B17,#REF!,Extrato!Q$3) -> #REF! | R17: =SUMIFS(#REF!,#REF!,Extrato!$B17,#REF!,Extrato!R$3) -> #REF! | S17: =SUMIFS(#REF!,#REF!,Extrato!$B17,#REF!,Extrato!S$3) -> #REF! | T17: =SUMIFS(#REF!,#REF!,Extrato!$B17,#REF!,Extrato!T$3) -> #REF! | U17: =SUMIFS(#REF!,#REF!,Extrato!$B17,#REF!,Extrato!U$3) -> #REF! | V17: =SUMIFS(#REF!,#REF!,Extrato!$B17,#REF!,Extrato!V$3) -> #REF! | W17: =SUMIFS(#REF!,#REF!,Extrato!$B17,#REF!,Extrato!W$3) -> #REF! | X17: =SUMIFS(#REF!,#REF!,Extrato!$B17,#REF!,Extrato!X$3) -> #REF! | ... AI17: =SUMIFS(#REF!,#REF!,Extrato!$B17,#REF!,Extrato!AI$3) -> #REF! | AJ17: 0 | AL17: =SUM(C17:AK17) -> #REF!
B18: 46003 | C18: =AL17 -> #REF! | D18: =SUMIFS(#REF!,#REF!,Extrato!$B18,#REF!,Extrato!D$3) -> #REF! | E18: =SUMIFS(#REF!,#REF!,Extrato!$B18,#REF!,Extrato!E$3) -> #REF! | F18: =SUMIFS(#REF!,#REF!,Extrato!$B18,#REF!,Extrato!F$3) -> #REF! | G18: =SUMIFS(#REF!,#REF!,Extrato!$B18,#REF!,Extrato!G$3) -> #REF! | H18: =SUMIFS(#REF!,#REF!,Extrato!$B18,#REF!,Extrato!H$3) -> #REF! | I18: =SUMIFS(#REF!,#REF!,Extrato!$B18,#REF!,Extrato!I$3) -> #REF! | J18: =SUMIFS(#REF!,#REF!,Extrato!$B18,#REF!,Extrato!J$3) -> #REF! | K18: =SUMIFS(#REF!,#REF!,Extrato!$B18,#REF!,Extrato!K$3) -> #REF! | ... O18: =SUMIFS(#REF!,#REF!,Extrato!$B18,#REF!,Extrato!O$3) -> #REF! | P18: =SUMIF(BetFlow!B:B,B18,BetFlow!J:J) -> 0 | Q18: =SUMIFS(#REF!,#REF!,Extrato!$B18,#REF!,Extrato!Q$3) -> #REF! | R18: =SUMIFS(#REF!,#REF!,Extrato!$B18,#REF!,Extrato!R$3) -> #REF! | S18: =SUMIFS(#REF!,#REF!,Extrato!$B18,#REF!,Extrato!S$3) -> #REF! | T18: =SUMIFS(#REF!,#REF!,Extrato!$B18,#REF!,Extrato!T$3) -> #REF! | U18: =SUMIFS(#REF!,#REF!,Extrato!$B18,#REF!,Extrato!U$3) -> #REF! | V18: =SUMIFS(#REF!,#REF!,Extrato!$B18,#REF!,Extrato!V$3) -> #REF! | W18: =SUMIFS(#REF!,#REF!,Extrato!$B18,#REF!,Extrato!W$3) -> #REF! | X18: =SUMIFS(#REF!,#REF!,Extrato!$B18,#REF!,Extrato!X$3) -> #REF! | ... AI18: =SUMIFS(#REF!,#REF!,Extrato!$B18,#REF!,Extrato!AI$3) -> #REF! | AJ18: 0 | AL18: =SUM(C18:AK18) -> #REF!
B19: 46004 | C19: =AL18 -> #REF! | D19: =SUMIFS(#REF!,#REF!,Extrato!$B19,#REF!,Extrato!D$3) -> #REF! | E19: =SUMIFS(#REF!,#REF!,Extrato!$B19,#REF!,Extrato!E$3) -> #REF! | F19: =SUMIFS(#REF!,#REF!,Extrato!$B19,#REF!,Extrato!F$3) -> #REF! | G19: =SUMIFS(#REF!,#REF!,Extrato!$B19,#REF!,Extrato!G$3) -> #REF! | H19: =SUMIFS(#REF!,#REF!,Extrato!$B19,#REF!,Extrato!H$3) -> #REF! | I19: =SUMIFS(#REF!,#REF!,Extrato!$B19,#REF!,Extrato!I$3) -> #REF! | J19: =SUMIFS(#REF!,#REF!,Extrato!$B19,#REF!,Extrato!J$3) -> #REF! | K19: =SUMIFS(#REF!,#REF!,Extrato!$B19,#REF!,Extrato!K$3) -> #REF! | ... O19: =SUMIFS(#REF!,#REF!,Extrato!$B19,#REF!,Extrato!O$3) -> #REF! | P19: =SUMIF(BetFlow!B:B,B19,BetFlow!J:J) -> 0 | Q19: =SUMIFS(#REF!,#REF!,Extrato!$B19,#REF!,Extrato!Q$3) -> #REF! | R19: =SUMIFS(#REF!,#REF!,Extrato!$B19,#REF!,Extrato!R$3) -> #REF! | S19: =SUMIFS(#REF!,#REF!,Extrato!$B19,#REF!,Extrato!S$3) -> #REF! | T19: =SUMIFS(#REF!,#REF!,Extrato!$B19,#REF!,Extrato!T$3) -> #REF! | U19: =SUMIFS(#REF!,#REF!,Extrato!$B19,#REF!,Extrato!U$3) -> #REF! | V19: =SUMIFS(#REF!,#REF!,Extrato!$B19,#REF!,Extrato!V$3) -> #REF! | W19: =SUMIFS(#REF!,#REF!,Extrato!$B19,#REF!,Extrato!W$3) -> #REF! | X19: =SUMIFS(#REF!,#REF!,Extrato!$B19,#REF!,Extrato!X$3) -> #REF! | ... AI19: =SUMIFS(#REF!,#REF!,Extrato!$B19,#REF!,Extrato!AI$3) -> #REF! | AJ19: 0 | AL19: =SUM(C19:AK19) -> #REF!
B20: 46005 | C20: =AL19 -> #REF! | D20: =SUMIFS(#REF!,#REF!,Extrato!$B20,#REF!,Extrato!D$3) -> #REF! | E20: =SUMIFS(#REF!,#REF!,Extrato!$B20,#REF!,Extrato!E$3) -> #REF! | F20: =SUMIFS(#REF!,#REF!,Extrato!$B20,#REF!,Extrato!F$3) -> #REF! | G20: =SUMIFS(#REF!,#REF!,Extrato!$B20,#REF!,Extrato!G$3) -> #REF! | H20: =SUMIFS(#REF!,#REF!,Extrato!$B20,#REF!,Extrato!H$3) -> #REF! | I20: =SUMIFS(#REF!,#REF!,Extrato!$B20,#REF!,Extrato!I$3) -> #REF! | J20: =SUMIFS(#REF!,#REF!,Extrato!$B20,#REF!,Extrato!J$3) -> #REF! | K20: =SUMIFS(#REF!,#REF!,Extrato!$B20,#REF!,Extrato!K$3) -> #REF! | ... O20: =SUMIFS(#REF!,#REF!,Extrato!$B20,#REF!,Extrato!O$3) -> #REF! | P20: =SUMIF(BetFlow!B:B,B20,BetFlow!J:J) -> 0 | Q20: =SUMIFS(#REF!,#REF!,Extrato!$B20,#REF!,Extrato!Q$3) -> #REF! | R20: =SUMIFS(#REF!,#REF!,Extrato!$B20,#REF!,Extrato!R$3) -> #REF! | S20: =SUMIFS(#REF!,#REF!,Extrato!$B20,#REF!,Extrato!S$3) -> #REF! | T20: =SUMIFS(#REF!,#REF!,Extrato!$B20,#REF!,Extrato!T$3) -> #REF! | U20: =SUMIFS(#REF!,#REF!,Extrato!$B20,#REF!,Extrato!U$3) -> #REF! | V20: =SUMIFS(#REF!,#REF!,Extrato!$B20,#REF!,Extrato!V$3) -> #REF! | W20: =SUMIFS(#REF!,#REF!,Extrato!$B20,#REF!,Extrato!W$3) -> #REF! | X20: =SUMIFS(#REF!,#REF!,Extrato!$B20,#REF!,Extrato!X$3) -> #REF! | ... AI20: =SUMIFS(#REF!,#REF!,Extrato!$B20,#REF!,Extrato!AI$3) -> #REF! | AJ20: 0 | AL20: =SUM(C20:AK20) -> #REF!
B21: 46006 | C21: =AL20 -> #REF! | D21: =SUMIFS(#REF!,#REF!,Extrato!$B21,#REF!,Extrato!D$3) -> #REF! | E21: =SUMIFS(#REF!,#REF!,Extrato!$B21,#REF!,Extrato!E$3) -> #REF! | F21: =SUMIFS(#REF!,#REF!,Extrato!$B21,#REF!,Extrato!F$3) -> #REF! | G21: =SUMIFS(#REF!,#REF!,Extrato!$B21,#REF!,Extrato!G$3) -> #REF! | H21: =SUMIFS(#REF!,#REF!,Extrato!$B21,#REF!,Extrato!H$3) -> #REF! | I21: =SUMIFS(#REF!,#REF!,Extrato!$B21,#REF!,Extrato!I$3) -> #REF! | J21: =SUMIFS(#REF!,#REF!,Extrato!$B21,#REF!,Extrato!J$3) -> #REF! | K21: =SUMIFS(#REF!,#REF!,Extrato!$B21,#REF!,Extrato!K$3) -> #REF! | ... O21: =SUMIFS(#REF!,#REF!,Extrato!$B21,#REF!,Extrato!O$3) -> #REF! | P21: =SUMIF(BetFlow!B:B,B21,BetFlow!J:J) -> 0 | Q21: =SUMIFS(#REF!,#REF!,Extrato!$B21,#REF!,Extrato!Q$3) -> #REF! | R21: =SUMIFS(#REF!,#REF!,Extrato!$B21,#REF!,Extrato!R$3) -> #REF! | S21: =SUMIFS(#REF!,#REF!,Extrato!$B21,#REF!,Extrato!S$3) -> #REF! | T21: =SUMIFS(#REF!,#REF!,Extrato!$B21,#REF!,Extrato!T$3) -> #REF! | U21: =SUMIFS(#REF!,#REF!,Extrato!$B21,#REF!,Extrato!U$3) -> #REF! | V21: =SUMIFS(#REF!,#REF!,Extrato!$B21,#REF!,Extrato!V$3) -> #REF! | W21: =SUMIFS(#REF!,#REF!,Extrato!$B21,#REF!,Extrato!W$3) -> #REF! | X21: =SUMIFS(#REF!,#REF!,Extrato!$B21,#REF!,Extrato!X$3) -> #REF! | ... AI21: =SUMIFS(#REF!,#REF!,Extrato!$B21,#REF!,Extrato!AI$3) -> #REF! | AJ21: 0 | AL21: =SUM(C21:AK21) -> #REF!
B22: 46007 | C22: =AL21 -> #REF! | D22: =SUMIFS(#REF!,#REF!,Extrato!$B22,#REF!,Extrato!D$3) -> #REF! | E22: =SUMIFS(#REF!,#REF!,Extrato!$B22,#REF!,Extrato!E$3) -> #REF! | F22: =SUMIFS(#REF!,#REF!,Extrato!$B22,#REF!,Extrato!F$3) -> #REF! | G22: =SUMIFS(#REF!,#REF!,Extrato!$B22,#REF!,Extrato!G$3) -> #REF! | H22: =SUMIFS(#REF!,#REF!,Extrato!$B22,#REF!,Extrato!H$3) -> #REF! | I22: =SUMIFS(#REF!,#REF!,Extrato!$B22,#REF!,Extrato!I$3) -> #REF! | J22: =SUMIFS(#REF!,#REF!,Extrato!$B22,#REF!,Extrato!J$3) -> #REF! | K22: =SUMIFS(#REF!,#REF!,Extrato!$B22,#REF!,Extrato!K$3) -> #REF! | ... O22: =SUMIFS(#REF!,#REF!,Extrato!$B22,#REF!,Extrato!O$3) -> #REF! | P22: =SUMIF(BetFlow!B:B,B22,BetFlow!J:J) -> 0 | Q22: =SUMIFS(#REF!,#REF!,Extrato!$B22,#REF!,Extrato!Q$3) -> #REF! | R22: =SUMIFS(#REF!,#REF!,Extrato!$B22,#REF!,Extrato!R$3) -> #REF! | S22: =SUMIFS(#REF!,#REF!,Extrato!$B22,#REF!,Extrato!S$3) -> #REF! | T22: =SUMIFS(#REF!,#REF!,Extrato!$B22,#REF!,Extrato!T$3) -> #REF! | U22: =SUMIFS(#REF!,#REF!,Extrato!$B22,#REF!,Extrato!U$3) -> #REF! | V22: =SUMIFS(#REF!,#REF!,Extrato!$B22,#REF!,Extrato!V$3) -> #REF! | W22: =SUMIFS(#REF!,#REF!,Extrato!$B22,#REF!,Extrato!W$3) -> #REF! | X22: =SUMIFS(#REF!,#REF!,Extrato!$B22,#REF!,Extrato!X$3) -> #REF! | ... AI22: =SUMIFS(#REF!,#REF!,Extrato!$B22,#REF!,Extrato!AI$3) -> #REF! | AJ22: 0 | AK22: -0.03 | AL22: =SUM(C22:AK22) -> #REF!
B23: 46008 | C23: =AL22 -> #REF! | D23: =SUMIFS(#REF!,#REF!,Extrato!$B23,#REF!,Extrato!D$3) -> #REF! | E23: =SUMIFS(#REF!,#REF!,Extrato!$B23,#REF!,Extrato!E$3) -> #REF! | F23: =SUMIFS(#REF!,#REF!,Extrato!$B23,#REF!,Extrato!F$3) -> #REF! | G23: =SUMIFS(#REF!,#REF!,Extrato!$B23,#REF!,Extrato!G$3) -> #REF! | H23: =SUMIFS(#REF!,#REF!,Extrato!$B23,#REF!,Extrato!H$3) -> #REF! | I23: =SUMIFS(#REF!,#REF!,Extrato!$B23,#REF!,Extrato!I$3) -> #REF! | J23: =SUMIFS(#REF!,#REF!,Extrato!$B23,#REF!,Extrato!J$3) -> #REF! | K23: =SUMIFS(#REF!,#REF!,Extrato!$B23,#REF!,Extrato!K$3) -> #REF! | ... O23: =SUMIFS(#REF!,#REF!,Extrato!$B23,#REF!,Extrato!O$3) -> #REF! | P23: =SUMIF(BetFlow!B:B,B23,BetFlow!J:J) -> 0 | Q23: =SUMIFS(#REF!,#REF!,Extrato!$B23,#REF!,Extrato!Q$3) -> #REF! | R23: =SUMIFS(#REF!,#REF!,Extrato!$B23,#REF!,Extrato!R$3) -> #REF! | S23: =SUMIFS(#REF!,#REF!,Extrato!$B23,#REF!,Extrato!S$3) -> #REF! | T23: =SUMIFS(#REF!,#REF!,Extrato!$B23,#REF!,Extrato!T$3) -> #REF! | U23: =SUMIFS(#REF!,#REF!,Extrato!$B23,#REF!,Extrato!U$3) -> #REF! | V23: =SUMIFS(#REF!,#REF!,Extrato!$B23,#REF!,Extrato!V$3) -> #REF! | W23: =SUMIFS(#REF!,#REF!,Extrato!$B23,#REF!,Extrato!W$3) -> #REF! | X23: =SUMIFS(#REF!,#REF!,Extrato!$B23,#REF!,Extrato!X$3) -> #REF! | ... AI23: =SUMIFS(#REF!,#REF!,Extrato!$B23,#REF!,Extrato!AI$3) -> #REF! | AJ23: 0 | AL23: =SUM(C23:AK23) -> #REF!
B24: 46009 | C24: =AL23 -> #REF! | D24: =SUMIFS(#REF!,#REF!,Extrato!$B24,#REF!,Extrato!D$3) -> #REF! | E24: =SUMIFS(#REF!,#REF!,Extrato!$B24,#REF!,Extrato!E$3) -> #REF! | F24: =SUMIFS(#REF!,#REF!,Extrato!$B24,#REF!,Extrato!F$3) -> #REF! | G24: =SUMIFS(#REF!,#REF!,Extrato!$B24,#REF!,Extrato!G$3) -> #REF! | H24: =SUMIFS(#REF!,#REF!,Extrato!$B24,#REF!,Extrato!H$3) -> #REF! | I24: =SUMIFS(#REF!,#REF!,Extrato!$B24,#REF!,Extrato!I$3) -> #REF! | J24: =SUMIFS(#REF!,#REF!,Extrato!$B24,#REF!,Extrato!J$3) -> #REF! | K24: =SUMIFS(#REF!,#REF!,Extrato!$B24,#REF!,Extrato!K$3) -> #REF! | ... O24: =SUMIFS(#REF!,#REF!,Extrato!$B24,#REF!,Extrato!O$3) -> #REF! | P24: =SUMIF(BetFlow!B:B,B24,BetFlow!J:J) -> 0 | Q24: =SUMIFS(#REF!,#REF!,Extrato!$B24,#REF!,Extrato!Q$3) -> #REF! | R24: =SUMIFS(#REF!,#REF!,Extrato!$B24,#REF!,Extrato!R$3) -> #REF! | S24: =SUMIFS(#REF!,#REF!,Extrato!$B24,#REF!,Extrato!S$3) -> #REF! | T24: =SUMIFS(#REF!,#REF!,Extrato!$B24,#REF!,Extrato!T$3) -> #REF! | U24: =SUMIFS(#REF!,#REF!,Extrato!$B24,#REF!,Extrato!U$3) -> #REF! | V24: =SUMIFS(#REF!,#REF!,Extrato!$B24,#REF!,Extrato!V$3) -> #REF! | W24: =SUMIFS(#REF!,#REF!,Extrato!$B24,#REF!,Extrato!W$3) -> #REF! | X24: =SUMIFS(#REF!,#REF!,Extrato!$B24,#REF!,Extrato!X$3) -> #REF! | ... AI24: =SUMIFS(#REF!,#REF!,Extrato!$B24,#REF!,Extrato!AI$3) -> #REF! | AJ24: 0 | AL24: =SUM(C24:AK24) -> #REF!
B25: 46010 | C25: =AL24 -> #REF! | D25: =SUMIFS(#REF!,#REF!,Extrato!$B25,#REF!,Extrato!D$3) -> #REF! | E25: =SUMIFS(#REF!,#REF!,Extrato!$B25,#REF!,Extrato!E$3) -> #REF! | F25: =SUMIFS(#REF!,#REF!,Extrato!$B25,#REF!,Extrato!F$3) -> #REF! | G25: =SUMIFS(#REF!,#REF!,Extrato!$B25,#REF!,Extrato!G$3) -> #REF! | H25: =SUMIFS(#REF!,#REF!,Extrato!$B25,#REF!,Extrato!H$3) -> #REF! | I25: =SUMIFS(#REF!,#REF!,Extrato!$B25,#REF!,Extrato!I$3) -> #REF! | J25: =SUMIFS(#REF!,#REF!,Extrato!$B25,#REF!,Extrato!J$3) -> #REF! | K25: =SUMIFS(#REF!,#REF!,Extrato!$B25,#REF!,Extrato!K$3) -> #REF! | ... O25: =SUMIFS(#REF!,#REF!,Extrato!$B25,#REF!,Extrato!O$3) -> #REF! | P25: =SUMIF(BetFlow!B:B,B25,BetFlow!J:J) -> 0 | Q25: =SUMIFS(#REF!,#REF!,Extrato!$B25,#REF!,Extrato!Q$3) -> #REF! | R25: =SUMIFS(#REF!,#REF!,Extrato!$B25,#REF!,Extrato!R$3) -> #REF! | S25: =SUMIFS(#REF!,#REF!,Extrato!$B25,#REF!,Extrato!S$3) -> #REF! | T25: =SUMIFS(#REF!,#REF!,Extrato!$B25,#REF!,Extrato!T$3) -> #REF! | U25: =SUMIFS(#REF!,#REF!,Extrato!$B25,#REF!,Extrato!U$3) -> #REF! | V25: =SUMIFS(#REF!,#REF!,Extrato!$B25,#REF!,Extrato!V$3) -> #REF! | W25: =SUMIFS(#REF!,#REF!,Extrato!$B25,#REF!,Extrato!W$3) -> #REF! | X25: =SUMIFS(#REF!,#REF!,Extrato!$B25,#REF!,Extrato!X$3) -> #REF! | ... AI25: =SUMIFS(#REF!,#REF!,Extrato!$B25,#REF!,Extrato!AI$3) -> #REF! | AJ25: 0 | AL25: =SUM(C25:AK25) -> #REF!
B26: 46011 | C26: =AL25 -> #REF! | D26: =SUMIFS(#REF!,#REF!,Extrato!$B26,#REF!,Extrato!D$3) -> #REF! | E26: =SUMIFS(#REF!,#REF!,Extrato!$B26,#REF!,Extrato!E$3) -> #REF! | F26: =SUMIFS(#REF!,#REF!,Extrato!$B26,#REF!,Extrato!F$3) -> #REF! | G26: =SUMIFS(#REF!,#REF!,Extrato!$B26,#REF!,Extrato!G$3) -> #REF! | H26: =SUMIFS(#REF!,#REF!,Extrato!$B26,#REF!,Extrato!H$3) -> #REF! | I26: =SUMIFS(#REF!,#REF!,Extrato!$B26,#REF!,Extrato!I$3) -> #REF! | J26: =SUMIFS(#REF!,#REF!,Extrato!$B26,#REF!,Extrato!J$3) -> #REF! | K26: =SUMIFS(#REF!,#REF!,Extrato!$B26,#REF!,Extrato!K$3) -> #REF! | ... O26: =SUMIFS(#REF!,#REF!,Extrato!$B26,#REF!,Extrato!O$3) -> #REF! | P26: =SUMIF(BetFlow!B:B,B26,BetFlow!J:J) -> 0 | Q26: =SUMIFS(#REF!,#REF!,Extrato!$B26,#REF!,Extrato!Q$3) -> #REF! | R26: =SUMIFS(#REF!,#REF!,Extrato!$B26,#REF!,Extrato!R$3) -> #REF! | S26: =SUMIFS(#REF!,#REF!,Extrato!$B26,#REF!,Extrato!S$3) -> #REF! | T26: =SUMIFS(#REF!,#REF!,Extrato!$B26,#REF!,Extrato!T$3) -> #REF! | U26: =SUMIFS(#REF!,#REF!,Extrato!$B26,#REF!,Extrato!U$3) -> #REF! | V26: =SUMIFS(#REF!,#REF!,Extrato!$B26,#REF!,Extrato!V$3) -> #REF! | W26: =SUMIFS(#REF!,#REF!,Extrato!$B26,#REF!,Extrato!W$3) -> #REF! | X26: =SUMIFS(#REF!,#REF!,Extrato!$B26,#REF!,Extrato!X$3) -> #REF! | ... AI26: =SUMIFS(#REF!,#REF!,Extrato!$B26,#REF!,Extrato!AI$3) -> #REF! | AJ26: 480 | AK26: -0.03 | AL26: =SUM(C26:AK26) -> #REF!
B27: 46012 | C27: =AL26 -> #REF! | D27: =SUMIFS(#REF!,#REF!,Extrato!$B27,#REF!,Extrato!D$3) -> #REF! | E27: =SUMIFS(#REF!,#REF!,Extrato!$B27,#REF!,Extrato!E$3) -> #REF! | F27: =SUMIFS(#REF!,#REF!,Extrato!$B27,#REF!,Extrato!F$3) -> #REF! | G27: =SUMIFS(#REF!,#REF!,Extrato!$B27,#REF!,Extrato!G$3) -> #REF! | H27: =SUMIFS(#REF!,#REF!,Extrato!$B27,#REF!,Extrato!H$3) -> #REF! | I27: =SUMIFS(#REF!,#REF!,Extrato!$B27,#REF!,Extrato!I$3) -> #REF! | J27: =SUMIFS(#REF!,#REF!,Extrato!$B27,#REF!,Extrato!J$3) -> #REF! | K27: =SUMIFS(#REF!,#REF!,Extrato!$B27,#REF!,Extrato!K$3) -> #REF! | ... O27: =SUMIFS(#REF!,#REF!,Extrato!$B27,#REF!,Extrato!O$3) -> #REF! | P27: =SUMIF(BetFlow!B:B,B27,BetFlow!J:J) -> 0 | Q27: =SUMIFS(#REF!,#REF!,Extrato!$B27,#REF!,Extrato!Q$3) -> #REF! | R27: =SUMIFS(#REF!,#REF!,Extrato!$B27,#REF!,Extrato!R$3) -> #REF! | S27: =SUMIFS(#REF!,#REF!,Extrato!$B27,#REF!,Extrato!S$3) -> #REF! | T27: =SUMIFS(#REF!,#REF!,Extrato!$B27,#REF!,Extrato!T$3) -> #REF! | U27: =SUMIFS(#REF!,#REF!,Extrato!$B27,#REF!,Extrato!U$3) -> #REF! | V27: =SUMIFS(#REF!,#REF!,Extrato!$B27,#REF!,Extrato!V$3) -> #REF! | W27: =SUMIFS(#REF!,#REF!,Extrato!$B27,#REF!,Extrato!W$3) -> #REF! | X27: =SUMIFS(#REF!,#REF!,Extrato!$B27,#REF!,Extrato!X$3) -> #REF! | ... AI27: =SUMIFS(#REF!,#REF!,Extrato!$B27,#REF!,Extrato!AI$3) -> #REF! | AJ27: 0 | AK27: -0.01 | AL27: =SUM(C27:AK27) -> #REF!
B28: 46017 | C28: =AL27 -> #REF! | D28: =SUMIFS(#REF!,#REF!,Extrato!$B28,#REF!,Extrato!D$3) -> #REF! | E28: =SUMIFS(#REF!,#REF!,Extrato!$B28,#REF!,Extrato!E$3) -> #REF! | F28: =SUMIFS(#REF!,#REF!,Extrato!$B28,#REF!,Extrato!F$3) -> #REF! | G28: =SUMIFS(#REF!,#REF!,Extrato!$B28,#REF!,Extrato!G$3) -> #REF! | H28: =SUMIFS(#REF!,#REF!,Extrato!$B28,#REF!,Extrato!H$3) -> #REF! | I28: =SUMIFS(#REF!,#REF!,Extrato!$B28,#REF!,Extrato!I$3) -> #REF! | J28: =SUMIFS(#REF!,#REF!,Extrato!$B28,#REF!,Extrato!J$3) -> #REF! | K28: =SUMIFS(#REF!,#REF!,Extrato!$B28,#REF!,Extrato!K$3) -> #REF! | ... O28: =SUMIFS(#REF!,#REF!,Extrato!$B28,#REF!,Extrato!O$3) -> #REF! | P28: =SUMIF(BetFlow!B:B,B28,BetFlow!J:J) -> 0 | Q28: =SUMIFS(#REF!,#REF!,Extrato!$B28,#REF!,Extrato!Q$3) -> #REF! | R28: =SUMIFS(#REF!,#REF!,Extrato!$B28,#REF!,Extrato!R$3) -> #REF! | S28: =SUMIFS(#REF!,#REF!,Extrato!$B28,#REF!,Extrato!S$3) -> #REF! | T28: =SUMIFS(#REF!,#REF!,Extrato!$B28,#REF!,Extrato!T$3) -> #REF! | U28: =SUMIFS(#REF!,#REF!,Extrato!$B28,#REF!,Extrato!U$3) -> #REF! | V28: =SUMIFS(#REF!,#REF!,Extrato!$B28,#REF!,Extrato!V$3) -> #REF! | W28: =SUMIFS(#REF!,#REF!,Extrato!$B28,#REF!,Extrato!W$3) -> #REF! | X28: =SUMIFS(#REF!,#REF!,Extrato!$B28,#REF!,Extrato!X$3) -> #REF! | ... AI28: =SUMIFS(#REF!,#REF!,Extrato!$B28,#REF!,Extrato!AI$3) -> #REF! | AJ28: 0 | AL28: =SUM(C28:AK28) -> #REF!
B29: 46018 | C29: =AL28 -> #REF! | D29: =SUMIFS(#REF!,#REF!,Extrato!$B29,#REF!,Extrato!D$3) -> #REF! | E29: =SUMIFS(#REF!,#REF!,Extrato!$B29,#REF!,Extrato!E$3) -> #REF! | F29: =SUMIFS(#REF!,#REF!,Extrato!$B29,#REF!,Extrato!F$3) -> #REF! | G29: =SUMIFS(#REF!,#REF!,Extrato!$B29,#REF!,Extrato!G$3) -> #REF! | H29: =SUMIFS(#REF!,#REF!,Extrato!$B29,#REF!,Extrato!H$3) -> #REF! | I29: =SUMIFS(#REF!,#REF!,Extrato!$B29,#REF!,Extrato!I$3) -> #REF! | J29: =SUMIFS(#REF!,#REF!,Extrato!$B29,#REF!,Extrato!J$3) -> #REF! | K29: =SUMIFS(#REF!,#REF!,Extrato!$B29,#REF!,Extrato!K$3) -> #REF! | ... O29: =SUMIFS(#REF!,#REF!,Extrato!$B29,#REF!,Extrato!O$3) -> #REF! | P29: =SUMIF(BetFlow!B:B,B29,BetFlow!J:J) -> 0 | Q29: =SUMIFS(#REF!,#REF!,Extrato!$B29,#REF!,Extrato!Q$3) -> #REF! | R29: =SUMIFS(#REF!,#REF!,Extrato!$B29,#REF!,Extrato!R$3) -> #REF! | S29: =SUMIFS(#REF!,#REF!,Extrato!$B29,#REF!,Extrato!S$3) -> #REF! | T29: =SUMIFS(#REF!,#REF!,Extrato!$B29,#REF!,Extrato!T$3) -> #REF! | U29: =SUMIFS(#REF!,#REF!,Extrato!$B29,#REF!,Extrato!U$3) -> #REF! | V29: =SUMIFS(#REF!,#REF!,Extrato!$B29,#REF!,Extrato!V$3) -> #REF! | W29: =SUMIFS(#REF!,#REF!,Extrato!$B29,#REF!,Extrato!W$3) -> #REF! | X29: =SUMIFS(#REF!,#REF!,Extrato!$B29,#REF!,Extrato!X$3) -> #REF! | ... AI29: =SUMIFS(#REF!,#REF!,Extrato!$B29,#REF!,Extrato!AI$3) -> #REF! | AJ29: 0 | AL29: =SUM(C29:AK29) -> #REF!
B30: 46019 | C30: =AL29 -> #REF! | D30: =SUMIFS(#REF!,#REF!,Extrato!$B30,#REF!,Extrato!D$3) -> #REF! | E30: =SUMIFS(#REF!,#REF!,Extrato!$B30,#REF!,Extrato!E$3) -> #REF! | F30: =SUMIFS(#REF!,#REF!,Extrato!$B30,#REF!,Extrato!F$3) -> #REF! | G30: =SUMIFS(#REF!,#REF!,Extrato!$B30,#REF!,Extrato!G$3) -> #REF! | H30: =SUMIFS(#REF!,#REF!,Extrato!$B30,#REF!,Extrato!H$3) -> #REF! | I30: =SUMIFS(#REF!,#REF!,Extrato!$B30,#REF!,Extrato!I$3) -> #REF! | J30: =SUMIFS(#REF!,#REF!,Extrato!$B30,#REF!,Extrato!J$3) -> #REF! | K30: =SUMIFS(#REF!,#REF!,Extrato!$B30,#REF!,Extrato!K$3) -> #REF! | ... O30: =SUMIFS(#REF!,#REF!,Extrato!$B30,#REF!,Extrato!O$3) -> #REF! | P30: =SUMIF(BetFlow!B:B,B30,BetFlow!J:J) -> 0 | Q30: =SUMIFS(#REF!,#REF!,Extrato!$B30,#REF!,Extrato!Q$3) -> #REF! | R30: =SUMIFS(#REF!,#REF!,Extrato!$B30,#REF!,Extrato!R$3) -> #REF! | S30: =SUMIFS(#REF!,#REF!,Extrato!$B30,#REF!,Extrato!S$3) -> #REF! | T30: =SUMIFS(#REF!,#REF!,Extrato!$B30,#REF!,Extrato!T$3) -> #REF! | U30: =SUMIFS(#REF!,#REF!,Extrato!$B30,#REF!,Extrato!U$3) -> #REF! | V30: =SUMIFS(#REF!,#REF!,Extrato!$B30,#REF!,Extrato!V$3) -> #REF! | W30: =SUMIFS(#REF!,#REF!,Extrato!$B30,#REF!,Extrato!W$3) -> #REF! | X30: =SUMIFS(#REF!,#REF!,Extrato!$B30,#REF!,Extrato!X$3) -> #REF! | ... AI30: =SUMIFS(#REF!,#REF!,Extrato!$B30,#REF!,Extrato!AI$3) -> #REF! | AJ30: 0 | AK30: -0.01 | AL30: =SUM(C30:AK30) -> #REF!
B31: 46021 | C31: =AL30 -> #REF! | D31: =SUMIFS(#REF!,#REF!,Extrato!$B31,#REF!,Extrato!D$3) -> #REF! | E31: =SUMIFS(#REF!,#REF!,Extrato!$B31,#REF!,Extrato!E$3) -> #REF! | F31: =SUMIFS(#REF!,#REF!,Extrato!$B31,#REF!,Extrato!F$3) -> #REF! | G31: =SUMIFS(#REF!,#REF!,Extrato!$B31,#REF!,Extrato!G$3) -> #REF! | H31: =SUMIFS(#REF!,#REF!,Extrato!$B31,#REF!,Extrato!H$3) -> #REF! | I31: =SUMIFS(#REF!,#REF!,Extrato!$B31,#REF!,Extrato!I$3) -> #REF! | J31: =SUMIFS(#REF!,#REF!,Extrato!$B31,#REF!,Extrato!J$3) -> #REF! | K31: =SUMIFS(#REF!,#REF!,Extrato!$B31,#REF!,Extrato!K$3) -> #REF! | ... O31: =SUMIFS(#REF!,#REF!,Extrato!$B31,#REF!,Extrato!O$3) -> #REF! | P31: =SUMIF(BetFlow!B:B,B31,BetFlow!J:J) -> 0 | Q31: =SUMIFS(#REF!,#REF!,Extrato!$B31,#REF!,Extrato!Q$3) -> #REF! | R31: =SUMIFS(#REF!,#REF!,Extrato!$B31,#REF!,Extrato!R$3) -> #REF! | S31: =SUMIFS(#REF!,#REF!,Extrato!$B31,#REF!,Extrato!S$3) -> #REF! | T31: =SUMIFS(#REF!,#REF!,Extrato!$B31,#REF!,Extrato!T$3) -> #REF! | U31: =SUMIFS(#REF!,#REF!,Extrato!$B31,#REF!,Extrato!U$3) -> #REF! | V31: =SUMIFS(#REF!,#REF!,Extrato!$B31,#REF!,Extrato!V$3) -> #REF! | W31: =SUMIFS(#REF!,#REF!,Extrato!$B31,#REF!,Extrato!W$3) -> #REF! | X31: =SUMIFS(#REF!,#REF!,Extrato!$B31,#REF!,Extrato!X$3) -> #REF! | ... AI31: =SUMIFS(#REF!,#REF!,Extrato!$B31,#REF!,Extrato!AI$3) -> #REF! | AJ31: -480 | AK31: 0.01 | AL31: =SUM(C31:AK31) -> #REF!
B32: 46022 | C32: =AL31 -> #REF! | D32: =SUMIFS(#REF!,#REF!,Extrato!$B32,#REF!,Extrato!D$3) -> #REF! | E32: =SUMIFS(#REF!,#REF!,Extrato!$B32,#REF!,Extrato!E$3) -> #REF! | F32: =SUMIFS(#REF!,#REF!,Extrato!$B32,#REF!,Extrato!F$3) -> #REF! | G32: =SUMIFS(#REF!,#REF!,Extrato!$B32,#REF!,Extrato!G$3) -> #REF! | H32: =SUMIFS(#REF!,#REF!,Extrato!$B32,#REF!,Extrato!H$3) -> #REF! | I32: =SUMIFS(#REF!,#REF!,Extrato!$B32,#REF!,Extrato!I$3) -> #REF! | J32: =SUMIFS(#REF!,#REF!,Extrato!$B32,#REF!,Extrato!J$3) -> #REF! | K32: =SUMIFS(#REF!,#REF!,Extrato!$B32,#REF!,Extrato!K$3) -> #REF! | ... O32: =SUMIFS(#REF!,#REF!,Extrato!$B32,#REF!,Extrato!O$3) -> #REF! | P32: =SUMIF(BetFlow!B:B,B32,BetFlow!J:J) -> 0 | Q32: =SUMIFS(#REF!,#REF!,Extrato!$B32,#REF!,Extrato!Q$3) -> #REF! | R32: =SUMIFS(#REF!,#REF!,Extrato!$B32,#REF!,Extrato!R$3) -> #REF! | S32: =SUMIFS(#REF!,#REF!,Extrato!$B32,#REF!,Extrato!S$3) -> #REF! | T32: =SUMIFS(#REF!,#REF!,Extrato!$B32,#REF!,Extrato!T$3) -> #REF! | U32: =SUMIFS(#REF!,#REF!,Extrato!$B32,#REF!,Extrato!U$3) -> #REF! | V32: =SUMIFS(#REF!,#REF!,Extrato!$B32,#REF!,Extrato!V$3) -> #REF! | W32: =SUMIFS(#REF!,#REF!,Extrato!$B32,#REF!,Extrato!W$3) -> #REF! | X32: =SUMIFS(#REF!,#REF!,Extrato!$B32,#REF!,Extrato!X$3) -> #REF! | ... AI32: =SUMIFS(#REF!,#REF!,Extrato!$B32,#REF!,Extrato!AI$3) -> #REF! | AJ32: 0 | AL32: =SUM(C32:AK32) -> #REF!
B33: 46023 | C33: =AL32 -> #REF! | D33: =SUMIFS(#REF!,#REF!,Extrato!$B33,#REF!,Extrato!D$3) -> #REF! | E33: =SUMIFS(#REF!,#REF!,Extrato!$B33,#REF!,Extrato!E$3) -> #REF! | F33: =SUMIFS(#REF!,#REF!,Extrato!$B33,#REF!,Extrato!F$3) -> #REF! | G33: =SUMIFS(#REF!,#REF!,Extrato!$B33,#REF!,Extrato!G$3) -> #REF! | H33: =SUMIFS(#REF!,#REF!,Extrato!$B33,#REF!,Extrato!H$3) -> #REF! | I33: =SUMIFS(#REF!,#REF!,Extrato!$B33,#REF!,Extrato!I$3) -> #REF! | J33: =SUMIFS(#REF!,#REF!,Extrato!$B33,#REF!,Extrato!J$3) -> #REF! | K33: =SUMIFS(#REF!,#REF!,Extrato!$B33,#REF!,Extrato!K$3) -> #REF! | ... O33: =SUMIFS(#REF!,#REF!,Extrato!$B33,#REF!,Extrato!O$3) -> #REF! | P33: =SUMIF(BetFlow!B:B,B33,BetFlow!J:J) -> 0 | Q33: =SUMIFS(#REF!,#REF!,Extrato!$B33,#REF!,Extrato!Q$3) -> #REF! | R33: =SUMIFS(#REF!,#REF!,Extrato!$B33,#REF!,Extrato!R$3) -> #REF! | S33: =SUMIFS(#REF!,#REF!,Extrato!$B33,#REF!,Extrato!S$3) -> #REF! | T33: =SUMIFS(#REF!,#REF!,Extrato!$B33,#REF!,Extrato!T$3) -> #REF! | U33: =SUMIFS(#REF!,#REF!,Extrato!$B33,#REF!,Extrato!U$3) -> #REF! | V33: =SUMIFS(#REF!,#REF!,Extrato!$B33,#REF!,Extrato!V$3) -> #REF! | W33: =SUMIFS(#REF!,#REF!,Extrato!$B33,#REF!,Extrato!W$3) -> #REF! | X33: =SUMIFS(#REF!,#REF!,Extrato!$B33,#REF!,Extrato!X$3) -> #REF! | ... AI33: =SUMIFS(#REF!,#REF!,Extrato!$B33,#REF!,Extrato!AI$3) -> #REF! | AJ33: 0 | AK33: -0.01 | AL33: =SUM(C33:AK33) -> #REF!
B34: 46024 | C34: =AL33 -> #REF! | D34: =SUMIFS(#REF!,#REF!,Extrato!$B34,#REF!,Extrato!D$3) -> #REF! | E34: =SUMIFS(#REF!,#REF!,Extrato!$B34,#REF!,Extrato!E$3) -> #REF! | F34: =SUMIFS(#REF!,#REF!,Extrato!$B34,#REF!,Extrato!F$3) -> #REF! | G34: =SUMIFS(#REF!,#REF!,Extrato!$B34,#REF!,Extrato!G$3) -> #REF! | H34: =SUMIFS(#REF!,#REF!,Extrato!$B34,#REF!,Extrato!H$3) -> #REF! | I34: =SUMIFS(#REF!,#REF!,Extrato!$B34,#REF!,Extrato!I$3) -> #REF! | J34: =SUMIFS(#REF!,#REF!,Extrato!$B34,#REF!,Extrato!J$3) -> #REF! | K34: =SUMIFS(#REF!,#REF!,Extrato!$B34,#REF!,Extrato!K$3) -> #REF! | ... O34: =SUMIFS(#REF!,#REF!,Extrato!$B34,#REF!,Extrato!O$3) -> #REF! | P34: =SUMIF(BetFlow!B:B,B34,BetFlow!J:J) -> 0 | Q34: =SUMIFS(#REF!,#REF!,Extrato!$B34,#REF!,Extrato!Q$3) -> #REF! | R34: =SUMIFS(#REF!,#REF!,Extrato!$B34,#REF!,Extrato!R$3) -> #REF! | S34: =SUMIFS(#REF!,#REF!,Extrato!$B34,#REF!,Extrato!S$3) -> #REF! | T34: =SUMIFS(#REF!,#REF!,Extrato!$B34,#REF!,Extrato!T$3) -> #REF! | U34: =SUMIFS(#REF!,#REF!,Extrato!$B34,#REF!,Extrato!U$3) -> #REF! | V34: =SUMIFS(#REF!,#REF!,Extrato!$B34,#REF!,Extrato!V$3) -> #REF! | W34: =SUMIFS(#REF!,#REF!,Extrato!$B34,#REF!,Extrato!W$3) -> #REF! | X34: =SUMIFS(#REF!,#REF!,Extrato!$B34,#REF!,Extrato!X$3) -> #REF! | ... AI34: =SUMIFS(#REF!,#REF!,Extrato!$B34,#REF!,Extrato!AI$3) -> #REF! | AJ34: 0 | AL34: =SUM(C34:AK34) -> #REF!
B35: 46025 | C35: =AL34 -> #REF! | D35: =SUMIFS(#REF!,#REF!,Extrato!$B35,#REF!,Extrato!D$3) -> #REF! | E35: =SUMIFS(#REF!,#REF!,Extrato!$B35,#REF!,Extrato!E$3) -> #REF! | F35: =SUMIFS(#REF!,#REF!,Extrato!$B35,#REF!,Extrato!F$3) -> #REF! | G35: =SUMIFS(#REF!,#REF!,Extrato!$B35,#REF!,Extrato!G$3) -> #REF! | H35: =SUMIFS(#REF!,#REF!,Extrato!$B35,#REF!,Extrato!H$3) -> #REF! | I35: =SUMIFS(#REF!,#REF!,Extrato!$B35,#REF!,Extrato!I$3) -> #REF! | J35: =SUMIFS(#REF!,#REF!,Extrato!$B35,#REF!,Extrato!J$3) -> #REF! | K35: =SUMIFS(#REF!,#REF!,Extrato!$B35,#REF!,Extrato!K$3) -> #REF! | ... O35: =SUMIFS(#REF!,#REF!,Extrato!$B35,#REF!,Extrato!O$3) -> #REF! | P35: =SUMIF(BetFlow!B:B,B35,BetFlow!J:J) -> 0 | Q35: =SUMIFS(#REF!,#REF!,Extrato!$B35,#REF!,Extrato!Q$3) -> #REF! | R35: =SUMIFS(#REF!,#REF!,Extrato!$B35,#REF!,Extrato!R$3) -> #REF! | S35: =SUMIFS(#REF!,#REF!,Extrato!$B35,#REF!,Extrato!S$3) -> #REF! | T35: =SUMIFS(#REF!,#REF!,Extrato!$B35,#REF!,Extrato!T$3) -> #REF! | U35: =SUMIFS(#REF!,#REF!,Extrato!$B35,#REF!,Extrato!U$3) -> #REF! | V35: =SUMIFS(#REF!,#REF!,Extrato!$B35,#REF!,Extrato!V$3) -> #REF! | W35: =SUMIFS(#REF!,#REF!,Extrato!$B35,#REF!,Extrato!W$3) -> #REF! | X35: =SUMIFS(#REF!,#REF!,Extrato!$B35,#REF!,Extrato!X$3) -> #REF! | ... AI35: =SUMIFS(#REF!,#REF!,Extrato!$B35,#REF!,Extrato!AI$3) -> #REF! | AJ35: 0 | AL35: =SUM(C35:AK35) -> #REF!
B36: 46026 | C36: =AL35 -> #REF! | D36: =SUMIFS(#REF!,#REF!,Extrato!$B36,#REF!,Extrato!D$3) -> #REF! | E36: =SUMIFS(#REF!,#REF!,Extrato!$B36,#REF!,Extrato!E$3) -> #REF! | F36: =SUMIFS(#REF!,#REF!,Extrato!$B36,#REF!,Extrato!F$3) -> #REF! | G36: =SUMIFS(#REF!,#REF!,Extrato!$B36,#REF!,Extrato!G$3) -> #REF! | H36: =SUMIFS(#REF!,#REF!,Extrato!$B36,#REF!,Extrato!H$3) -> #REF! | I36: =SUMIFS(#REF!,#REF!,Extrato!$B36,#REF!,Extrato!I$3) -> #REF! | J36: =SUMIFS(#REF!,#REF!,Extrato!$B36,#REF!,Extrato!J$3) -> #REF! | K36: =SUMIFS(#REF!,#REF!,Extrato!$B36,#REF!,Extrato!K$3) -> #REF! | ... O36: =SUMIFS(#REF!,#REF!,Extrato!$B36,#REF!,Extrato!O$3) -> #REF! | P36: =SUMIF(BetFlow!B:B,B36,BetFlow!J:J) -> 0 | Q36: =SUMIFS(#REF!,#REF!,Extrato!$B36,#REF!,Extrato!Q$3) -> #REF! | R36: =SUMIFS(#REF!,#REF!,Extrato!$B36,#REF!,Extrato!R$3) -> #REF! | S36: =SUMIFS(#REF!,#REF!,Extrato!$B36,#REF!,Extrato!S$3) -> #REF! | T36: =SUMIFS(#REF!,#REF!,Extrato!$B36,#REF!,Extrato!T$3) -> #REF! | U36: =SUMIFS(#REF!,#REF!,Extrato!$B36,#REF!,Extrato!U$3) -> #REF! | V36: =SUMIFS(#REF!,#REF!,Extrato!$B36,#REF!,Extrato!V$3) -> #REF! | W36: =SUMIFS(#REF!,#REF!,Extrato!$B36,#REF!,Extrato!W$3) -> #REF! | X36: =SUMIFS(#REF!,#REF!,Extrato!$B36,#REF!,Extrato!X$3) -> #REF! | ... AI36: =SUMIFS(#REF!,#REF!,Extrato!$B36,#REF!,Extrato!AI$3) -> #REF! | AJ36: 0 | AK36: -0.03 | AL36: =SUM(C36:AK36) -> #REF!
B37: 46027 | C37: =AL36 -> #REF! | D37: =SUMIFS(#REF!,#REF!,Extrato!$B37,#REF!,Extrato!D$3) -> #REF! | E37: =SUMIFS(#REF!,#REF!,Extrato!$B37,#REF!,Extrato!E$3) -> #REF! | F37: =SUMIFS(#REF!,#REF!,Extrato!$B37,#REF!,Extrato!F$3) -> #REF! | G37: =SUMIFS(#REF!,#REF!,Extrato!$B37,#REF!,Extrato!G$3) -> #REF! | H37: =SUMIFS(#REF!,#REF!,Extrato!$B37,#REF!,Extrato!H$3) -> #REF! | I37: =SUMIFS(#REF!,#REF!,Extrato!$B37,#REF!,Extrato!I$3) -> #REF! | J37: =SUMIFS(#REF!,#REF!,Extrato!$B37,#REF!,Extrato!J$3) -> #REF! | K37: =SUMIFS(#REF!,#REF!,Extrato!$B37,#REF!,Extrato!K$3) -> #REF! | ... O37: =SUMIFS(#REF!,#REF!,Extrato!$B37,#REF!,Extrato!O$3) -> #REF! | P37: =SUMIF(BetFlow!B:B,B37,BetFlow!J:J) -> 0 | Q37: =SUMIFS(#REF!,#REF!,Extrato!$B37,#REF!,Extrato!Q$3) -> #REF! | R37: =SUMIFS(#REF!,#REF!,Extrato!$B37,#REF!,Extrato!R$3) -> #REF! | S37: =SUMIFS(#REF!,#REF!,Extrato!$B37,#REF!,Extrato!S$3) -> #REF! | T37: =SUMIFS(#REF!,#REF!,Extrato!$B37,#REF!,Extrato!T$3) -> #REF! | U37: =SUMIFS(#REF!,#REF!,Extrato!$B37,#REF!,Extrato!U$3) -> #REF! | V37: =SUMIFS(#REF!,#REF!,Extrato!$B37,#REF!,Extrato!V$3) -> #REF! | W37: =SUMIFS(#REF!,#REF!,Extrato!$B37,#REF!,Extrato!W$3) -> #REF! | X37: =SUMIFS(#REF!,#REF!,Extrato!$B37,#REF!,Extrato!X$3) -> #REF! | ... AI37: =SUMIFS(#REF!,#REF!,Extrato!$B37,#REF!,Extrato!AI$3) -> #REF! | AJ37: 0 | AK37: -0.02 | AL37: =SUM(C37:AK37) -> #REF!
B38: 46028 | C38: =AL37 -> #REF! | D38: =SUMIFS(#REF!,#REF!,Extrato!$B38,#REF!,Extrato!D$3) -> #REF! | E38: =SUMIFS(#REF!,#REF!,Extrato!$B38,#REF!,Extrato!E$3) -> #REF! | F38: =SUMIFS(#REF!,#REF!,Extrato!$B38,#REF!,Extrato!F$3) -> #REF! | G38: =SUMIFS(#REF!,#REF!,Extrato!$B38,#REF!,Extrato!G$3) -> #REF! | H38: =SUMIFS(#REF!,#REF!,Extrato!$B38,#REF!,Extrato!H$3) -> #REF! | I38: =SUMIFS(#REF!,#REF!,Extrato!$B38,#REF!,Extrato!I$3) -> #REF! | J38: =SUMIFS(#REF!,#REF!,Extrato!$B38,#REF!,Extrato!J$3) -> #REF! | K38: =SUMIFS(#REF!,#REF!,Extrato!$B38,#REF!,Extrato!K$3) -> #REF! | ... O38: =SUMIFS(#REF!,#REF!,Extrato!$B38,#REF!,Extrato!O$3) -> #REF! | P38: =SUMIF(BetFlow!B:B,B38,BetFlow!J:J) -> 0 | Q38: =SUMIFS(#REF!,#REF!,Extrato!$B38,#REF!,Extrato!Q$3) -> #REF! | R38: =SUMIFS(#REF!,#REF!,Extrato!$B38,#REF!,Extrato!R$3) -> #REF! | S38: =SUMIFS(#REF!,#REF!,Extrato!$B38,#REF!,Extrato!S$3) -> #REF! | T38: =SUMIFS(#REF!,#REF!,Extrato!$B38,#REF!,Extrato!T$3) -> #REF! | U38: =SUMIFS(#REF!,#REF!,Extrato!$B38,#REF!,Extrato!U$3) -> #REF! | V38: =SUMIFS(#REF!,#REF!,Extrato!$B38,#REF!,Extrato!V$3) -> #REF! | W38: =SUMIFS(#REF!,#REF!,Extrato!$B38,#REF!,Extrato!W$3) -> #REF! | X38: =SUMIFS(#REF!,#REF!,Extrato!$B38,#REF!,Extrato!X$3) -> #REF! | ... AI38: =SUMIFS(#REF!,#REF!,Extrato!$B38,#REF!,Extrato!AI$3) -> #REF! | AJ38: 0 | AK38: -0.01 | AL38: =SUM(C38:AK38) -> #REF!
B39: 46029 | C39: =AL38 -> #REF! | D39: =SUMIFS(#REF!,#REF!,Extrato!$B39,#REF!,Extrato!D$3) -> #REF! | E39: =SUMIFS(#REF!,#REF!,Extrato!$B39,#REF!,Extrato!E$3) -> #REF! | F39: =SUMIFS(#REF!,#REF!,Extrato!$B39,#REF!,Extrato!F$3) -> #REF! | G39: =SUMIFS(#REF!,#REF!,Extrato!$B39,#REF!,Extrato!G$3) -> #REF! | H39: =SUMIFS(#REF!,#REF!,Extrato!$B39,#REF!,Extrato!H$3) -> #REF! | I39: =SUMIFS(#REF!,#REF!,Extrato!$B39,#REF!,Extrato!I$3) -> #REF! | J39: =SUMIFS(#REF!,#REF!,Extrato!$B39,#REF!,Extrato!J$3) -> #REF! | K39: =SUMIFS(#REF!,#REF!,Extrato!$B39,#REF!,Extrato!K$3) -> #REF! | ... O39: =SUMIFS(#REF!,#REF!,Extrato!$B39,#REF!,Extrato!O$3) -> #REF! | P39: =SUMIF(BetFlow!B:B,B39,BetFlow!J:J) -> 0 | Q39: =SUMIFS(#REF!,#REF!,Extrato!$B39,#REF!,Extrato!Q$3) -> #REF! | R39: =SUMIFS(#REF!,#REF!,Extrato!$B39,#REF!,Extrato!R$3) -> #REF! | S39: =SUMIFS(#REF!,#REF!,Extrato!$B39,#REF!,Extrato!S$3) -> #REF! | T39: =SUMIFS(#REF!,#REF!,Extrato!$B39,#REF!,Extrato!T$3) -> #REF! | U39: =SUMIFS(#REF!,#REF!,Extrato!$B39,#REF!,Extrato!U$3) -> #REF! | V39: =SUMIFS(#REF!,#REF!,Extrato!$B39,#REF!,Extrato!V$3) -> #REF! | W39: =SUMIFS(#REF!,#REF!,Extrato!$B39,#REF!,Extrato!W$3) -> #REF! | X39: =SUMIFS(#REF!,#REF!,Extrato!$B39,#REF!,Extrato!X$3) -> #REF! | ... AI39: =SUMIFS(#REF!,#REF!,Extrato!$B39,#REF!,Extrato!AI$3) -> #REF! | AJ39: 0 | AK39: 0.01 | AL39: =SUM(C39:AK39) -> #REF!
B40: 46030 | C40: =AL39 -> #REF! | D40: =SUMIFS(#REF!,#REF!,Extrato!$B40,#REF!,Extrato!D$3) -> #REF! | E40: =SUMIFS(#REF!,#REF!,Extrato!$B40,#REF!,Extrato!E$3) -> #REF! | F40: =SUMIFS(#REF!,#REF!,Extrato!$B40,#REF!,Extrato!F$3) -> #REF! | G40: =SUMIFS(#REF!,#REF!,Extrato!$B40,#REF!,Extrato!G$3) -> #REF! | H40: =SUMIFS(#REF!,#REF!,Extrato!$B40,#REF!,Extrato!H$3) -> #REF! | I40: =SUMIFS(#REF!,#REF!,Extrato!$B40,#REF!,Extrato!I$3) -> #REF! | J40: =SUMIFS(#REF!,#REF!,Extrato!$B40,#REF!,Extrato!J$3) -> #REF! | K40: =SUMIFS(#REF!,#REF!,Extrato!$B40,#REF!,Extrato!K$3) -> #REF! | ... O40: =SUMIFS(#REF!,#REF!,Extrato!$B40,#REF!,Extrato!O$3) -> #REF! | P40: =SUMIF(BetFlow!B:B,B40,BetFlow!J:J) -> 0 | Q40: =SUMIFS(#REF!,#REF!,Extrato!$B40,#REF!,Extrato!Q$3) -> #REF! | R40: =SUMIFS(#REF!,#REF!,Extrato!$B40,#REF!,Extrato!R$3) -> #REF! | S40: =SUMIFS(#REF!,#REF!,Extrato!$B40,#REF!,Extrato!S$3) -> #REF! | T40: =SUMIFS(#REF!,#REF!,Extrato!$B40,#REF!,Extrato!T$3) -> #REF! | U40: =SUMIFS(#REF!,#REF!,Extrato!$B40,#REF!,Extrato!U$3) -> #REF! | V40: =SUMIFS(#REF!,#REF!,Extrato!$B40,#REF!,Extrato!V$3) -> #REF! | W40: =SUMIFS(#REF!,#REF!,Extrato!$B40,#REF!,Extrato!W$3) -> #REF! | X40: =SUMIFS(#REF!,#REF!,Extrato!$B40,#REF!,Extrato!X$3) -> #REF! | ... AI40: =SUMIFS(#REF!,#REF!,Extrato!$B40,#REF!,Extrato!AI$3) -> #REF! | AJ40: 0 | AL40: =SUM(C40:AK40) -> #REF!
B41: 46031 | C41: =AL40 -> #REF! | D41: =SUMIFS(#REF!,#REF!,Extrato!$B41,#REF!,Extrato!D$3) -> #REF! | E41: =SUMIFS(#REF!,#REF!,Extrato!$B41,#REF!,Extrato!E$3) -> #REF! | F41: =SUMIFS(#REF!,#REF!,Extrato!$B41,#REF!,Extrato!F$3) -> #REF! | G41: =SUMIFS(#REF!,#REF!,Extrato!$B41,#REF!,Extrato!G$3) -> #REF! | H41: =SUMIFS(#REF!,#REF!,Extrato!$B41,#REF!,Extrato!H$3) -> #REF! | I41: =SUMIFS(#REF!,#REF!,Extrato!$B41,#REF!,Extrato!I$3) -> #REF! | J41: =SUMIFS(#REF!,#REF!,Extrato!$B41,#REF!,Extrato!J$3) -> #REF! | K41: =SUMIFS(#REF!,#REF!,Extrato!$B41,#REF!,Extrato!K$3) -> #REF! | ... O41: =SUMIFS(#REF!,#REF!,Extrato!$B41,#REF!,Extrato!O$3) -> #REF! | P41: =SUMIF(BetFlow!B:B,B41,BetFlow!J:J) -> 0 | Q41: =SUMIFS(#REF!,#REF!,Extrato!$B41,#REF!,Extrato!Q$3) -> #REF! | R41: =SUMIFS(#REF!,#REF!,Extrato!$B41,#REF!,Extrato!R$3) -> #REF! | S41: =SUMIFS(#REF!,#REF!,Extrato!$B41,#REF!,Extrato!S$3) -> #REF! | T41: =SUMIFS(#REF!,#REF!,Extrato!$B41,#REF!,Extrato!T$3) -> #REF! | U41: =SUMIFS(#REF!,#REF!,Extrato!$B41,#REF!,Extrato!U$3) -> #REF! | V41: =SUMIFS(#REF!,#REF!,Extrato!$B41,#REF!,Extrato!V$3) -> #REF! | W41: =SUMIFS(#REF!,#REF!,Extrato!$B41,#REF!,Extrato!W$3) -> #REF! | X41: =SUMIFS(#REF!,#REF!,Extrato!$B41,#REF!,Extrato!X$3) -> #REF! | ... AI41: =SUMIFS(#REF!,#REF!,Extrato!$B41,#REF!,Extrato!AI$3) -> #REF! | AJ41: 0 | AL41: =SUM(C41:AK41) -> #REF!
B42: 46032 | C42: =AL41 -> #REF! | D42: =SUMIFS(#REF!,#REF!,Extrato!$B42,#REF!,Extrato!D$3) -> #REF! | E42: =SUMIFS(#REF!,#REF!,Extrato!$B42,#REF!,Extrato!E$3) -> #REF! | F42: =SUMIFS(#REF!,#REF!,Extrato!$B42,#REF!,Extrato!F$3) -> #REF! | G42: =SUMIFS(#REF!,#REF!,Extrato!$B42,#REF!,Extrato!G$3) -> #REF! | H42: =SUMIFS(#REF!,#REF!,Extrato!$B42,#REF!,Extrato!H$3) -> #REF! | I42: =SUMIFS(#REF!,#REF!,Extrato!$B42,#REF!,Extrato!I$3) -> #REF! | J42: =SUMIFS(#REF!,#REF!,Extrato!$B42,#REF!,Extrato!J$3) -> #REF! | K42: =SUMIFS(#REF!,#REF!,Extrato!$B42,#REF!,Extrato!K$3) -> #REF! | ... O42: =SUMIFS(#REF!,#REF!,Extrato!$B42,#REF!,Extrato!O$3) -> #REF! | P42: =SUMIF(BetFlow!B:B,B42,BetFlow!J:J) -> 0 | Q42: =SUMIFS(#REF!,#REF!,Extrato!$B42,#REF!,Extrato!Q$3) -> #REF! | R42: =SUMIFS(#REF!,#REF!,Extrato!$B42,#REF!,Extrato!R$3) -> #REF! | S42: =SUMIFS(#REF!,#REF!,Extrato!$B42,#REF!,Extrato!S$3) -> #REF! | T42: =SUMIFS(#REF!,#REF!,Extrato!$B42,#REF!,Extrato!T$3) -> #REF! | U42: =SUMIFS(#REF!,#REF!,Extrato!$B42,#REF!,Extrato!U$3) -> #REF! | V42: =SUMIFS(#REF!,#REF!,Extrato!$B42,#REF!,Extrato!V$3) -> #REF! | W42: =SUMIFS(#REF!,#REF!,Extrato!$B42,#REF!,Extrato!W$3) -> #REF! | X42: =SUMIFS(#REF!,#REF!,Extrato!$B42,#REF!,Extrato!X$3) -> #REF! | ... AI42: =SUMIFS(#REF!,#REF!,Extrato!$B42,#REF!,Extrato!AI$3) -> #REF! | AJ42: 0 | AK42: -0.04 | AL42: =SUM(C42:AK42) -> #REF!
...

Sheet Base
B2: Evento / Mercado | C2: Exchange | D2: Data de liquidação | E2: L/P Líquido | F2: Comissão% | G2: L/P Bruto | H2: Método | I2: Placar | J2: Odd | K2: Stake/Responsabilidade | L2: Data | M2: ComissãoR$ | N2: Stakes | O2: Resultado_Binario | P2: Campeonato | Q2: Casa | R2: Visitante | S2: Confronto
B3: FC Luzern vs FC Winterthur / Correct Score | C3: Fulltbet | D3: 45990.765 | E3: 11.3645 | F3: 0.045 | G3: =IF(E3>0,E3/(1-F3),E3) -> 11.9 | H3: OMQB | I3: 0x1 | J3: 9.4 | K3: 99.96 | L3: =INT(base[[#This Row],[Data de liquidação]]) -> 45990 | M3: =base[[#This Row],[L/P Bruto]]-base[[#This Row],[L/P Líquido]] -> 0.5355 | N3: =base[[#This Row],[L/P Líquido]]/base[[#This Row],[Stake/Responsabilidade]] -> 0.11369048 | O3: =IF(base[[#This Row],[L/P Líquido]]>0,1,0) -> 1 | Q3: =LEFT(base[[#This Row],[Evento / Mercado]],FIND("vs",base[[#This Row],[Evento / Mercado]])-2) -> FC Luzern | R3: =IF(ISNUMBER(FIND("/",base[[#This Row],[Evento / Mercado]])),MID(base[[#This Row],[Evento / Mercado]],FIND("vs",base[[#This Row],[Evento / Mercado]])+3,FIND("/",base[[#This Row],[Evento / Mercado]])-FIND("vs",base[[#This Row],[Evento / Mercado]])-4),RIGHT(base[[#This Row],[Evento / Mercado]],LEN(base[[#This Row],[Evento / Mercado]])-FIND("vs",base[[#This Row],[Evento / Mercado]])-2)) -> FC Winterthur | S3: =LEFT(base[[#This Row],[Evento / Mercado]],FIND("/",base[[#This Row],[Evento / Mercado]])-2) -> FC Luzern vs FC Winterthur | T3: 11.9 | U3: =T3*0.955 -> 11.3645
B4: FC Luzern vs FC Winterthur / Correct Score | C4: Fulltbet | D4: 45990.765 | E4: 19.1 | F4: 0.045 | G4: =IF(E4>0,E4/(1-F4),E4) -> 20 | H4: OMQB | I4: 1x0 | J4: 6 | K4: 100 | L4: =INT(base[[#This Row],[Data de liquidação]]) -> 45990 | M4: =base[[#This Row],[L/P Bruto]]-base[[#This Row],[L/P Líquido]] -> 0.9 | N4: =base[[#This Row],[L/P Líquido]]/base[[#This Row],[Stake/Responsabilidade]] -> 0.191 | O4: =IF(base[[#This Row],[L/P Líquido]]>0,1,0) -> 1 | Q4: =LEFT(base[[#This Row],[Evento / Mercado]],FIND("vs",base[[#This Row],[Evento / Mercado]])-2) -> FC Luzern | R4: =IF(ISNUMBER(FIND("/",base[[#This Row],[Evento / Mercado]])),MID(base[[#This Row],[Evento / Mercado]],FIND("vs",base[[#This Row],[Evento / Mercado]])+3,FIND("/",base[[#This Row],[Evento / Mercado]])-FIND("vs",base[[#This Row],[Evento / Mercado]])-4),RIGHT(base[[#This Row],[Evento / Mercado]],LEN(base[[#This Row],[Evento / Mercado]])-FIND("vs",base[[#This Row],[Evento / Mercado]])-2)) -> FC Winterthur | S4: =LEFT(base[[#This Row],[Evento / Mercado]],FIND("/",base[[#This Row],[Evento / Mercado]])-2) -> FC Luzern vs FC Winterthur | T4: 20 | U4: =T4*0.955 -> 19.1
B5: AC Milan vs Lazio / Correct Score | C5: Fulltbet | D5: 45990.786 | E5: 8.68 | F5: 0.045 | G5: =IF(E5>0,E5/(1-F5),E5) -> 9.0890052 | H5: OMQB | I5: 0x1 | J5: 12 | K5: 99.99 | L5: =INT(base[[#This Row],[Data de liquidação]]) -> 45990 | M5: =base[[#This Row],[L/P Bruto]]-base[[#This Row],[L/P Líquido]] -> 0.40900524 | N5: =base[[#This Row],[L/P Líquido]]/base[[#This Row],[Stake/Responsabilidade]] -> 0.086808681 | O5: =IF(base[[#This Row],[L/P Líquido]]>0,1,0) -> 1 | Q5: =LEFT(base[[#This Row],[Evento / Mercado]],FIND("vs",base[[#This Row],[Evento / Mercado]])-2) -> AC Milan | R5: =IF(ISNUMBER(FIND("/",base[[#This Row],[Evento / Mercado]])),MID(base[[#This Row],[Evento / Mercado]],FIND("vs",base[[#This Row],[Evento / Mercado]])+3,FIND("/",base[[#This Row],[Evento / Mercado]])-FIND("vs",base[[#This Row],[Evento / Mercado]])-4),RIGHT(base[[#This Row],[Evento / Mercado]],LEN(base[[#This Row],[Evento / Mercado]])-FIND("vs",base[[#This Row],[Evento / Mercado]])-2)) -> Lazio | S5: =LEFT(base[[#This Row],[Evento / Mercado]],FIND("/",base[[#This Row],[Evento / Mercado]])-2) -> AC Milan vs Lazio
B6: Olympique Marseille vs Toulouse FC / Correct Score | C6: Fulltbet | D6: 45990.792 | E6: 11.10665 | F6: 0.045 | G6: =IF(E6>0,E6/(1-F6),E6) -> 11.63 | H6: OMQB | I6: 1x0 | J6: 9.6 | K6: 100.02 | L6: =INT(base[[#This Row],[Data de liquidação]]) -> 45990 | M6: =base[[#This Row],[L/P Bruto]]-base[[#This Row],[L/P Líquido]] -> 0.52335 | N6: =base[[#This Row],[L/P Líquido]]/base[[#This Row],[Stake/Responsabilidade]] -> 0.11104429 | O6: =IF(base[[#This Row],[L/P Líquido]]>0,1,0) -> 1 | Q6: =LEFT(base[[#This Row],[Evento / Mercado]],FIND("vs",base[[#This Row],[Evento / Mercado]])-2) -> Olympique Marseille | R6: =IF(ISNUMBER(FIND("/",base[[#This Row],[Evento / Mercado]])),MID(base[[#This Row],[Evento / Mercado]],FIND("vs",base[[#This Row],[Evento / Mercado]])+3,FIND("/",base[[#This Row],[Evento / Mercado]])-FIND("vs",base[[#This Row],[Evento / Mercado]])-4),RIGHT(base[[#This Row],[Evento / Mercado]],LEN(base[[#This Row],[Evento / Mercado]])-FIND("vs",base[[#This Row],[Evento / Mercado]])-2)) -> Toulouse FC | S6: =LEFT(base[[#This Row],[Evento / Mercado]],FIND("/",base[[#This Row],[Evento / Mercado]])-2) -> Olympique Marseille vs Toulouse FC | T6: 11.63 | U6: =T6*0.955 -> 11.10665
